Workbook

Sheet Dados
B2: FUNDO | C2: CNPJ | D2: Código Anbima
B3: Geraes | C3: 09.720.734/0001-10 | D3: 216658 | G3: capitania | K3: Ativo: | L3: FIDC
B4: ARX Denali | C4: 41.888.219/0001-56 | D4: 634468 | H4: arx
B5: Capitania Top | C5: 13.615.411/0001-33 | D5: 284491 | I5: FIDC | K5: Vai aparecer | L5: capitania
B6: Riza Lotus | C6: 36.498.670/0001-27 | D6: 531553 | I6: FIDC | L6: a partir do dia que o fundo que ela investiu teve o ativo
B7: Western Asset Total | C7: 28.320.756/0001-37 | D7: 489956 | H7: riza
B8: Daycoval Classic | C8: 10.783.480/0001-68 | D8: 259624 | I8: Debenture
B9: Iridium Apollo | C9: 26.978.438/0001-32 | D9: 456497 | H9: western
B10: Porto Seguro FIRF | C10: 18.719.154/0001-01 | D10: 361445 | I10: ação
B11: Nu Reserva Imediata | C11: 42.699.466/0001-77 | D11: 635091
B12: Inter Conservador | C12: 20.879.578/0001-77 | D12: 387444
B13: Absolute Atenas | C13: 48.096.589/0001-08 | D13: 677930
B14: Geraes 30 | C14: 29.044.189/0001-04 | D14: 462276
B15: Daycoval Classic 30 | C15: 29.250.121/0001-73 | D15: 470473
B16: Riza Lotus Plus | C16: 43.917.493/0001-31 | D16: 620955
B17: ARX Vinson Advisory | C17: 41.888.492/0001-80 | D17: 601462
B18: Sparta Max Advisory | C18: 32.757.330/0001-12 | D18: 493831
B19: Polo Crédito Corporativo | C19: 31.455.879/0001-90 | D19: 478008
B20: Iridium Titan Advisory | C20: 32.756.812/0001-58 | D20: 494607
B21: Porto Seguro Ipê | C21: 35.378.376/0001-19 | D21: 523666
B22: Sparta Top Advisory | C22: 32.846.811/0001-02 | D22: 494089
... B28: Absolute Olimpia | C28: 48.986.106/0001-32 | D28: 687138

Sheet Abr26
C2: LEGENDA: | H2: Fundo D+1 | I2: PL | J2: Caixa | L2: Bancários | N2: Corporativo | P2: FIDC | R2: FII | T2: Outros | W2: Obs: | Y2: Δ Caixa | Z2: Δ Bancários | AA2: Δ Corporativo | AB2: Δ FIDC | AC2: Δ FII | AE2: Δ Caixa | AF2: Δ Bancários | AG2: Δ Corporativo | AH2: Δ FIDC | AI2: Δ FII | AK2: Var. PL | AL2: % | AO2: LEGENDA:
B3: Bancário | C3: Corporativo | D3: Caixa | F3: =J3+L3+N3+P3+R3+T3 -> 1 | H3: Geraes | I3: 5.4246401e+08 | J3: 0.5608 | K3: =+J3*$I3 -> 3.0421382e+08 | L3: 0.2202 | M3: =+L3*$I3 -> 1.1945058e+08 | N3: 0.1751 | O3: =+N3*$I3 -> 94985448 | P3: 0.0446 | Q3: =+P3*$I3 -> 24193895 | R3: 0 | S3: =+R3*$I3 -> 0 | T3: -0.0007 | U3: =+T3*$I3 -> -379724.81 | Y3: =K3-'Mar26'!K3 -> -2014419.8 | Z3: =M3-'Mar26'!M3 -> -4343818.5 | AA3: =O3-'Mar26'!O3 -> -4417607.4 | AB3: =Q3-'Mar26'!Q3 -> -4039914.2 | AC3: =+S3-'Mar26'!S3 -> 0 | AE3: =J3-'Mar26'!J3 -> 0.0109 | AF3: =L3-'Mar26'!L3 -> -0.0021 | AG3: =N3-'Mar26'!N3 -> -0.0034 | AH3: =P3-'Mar26'!P3 -> -0.0061 | AI3: =R3-'Mar26'!R3 -> 0 | AK3: =I3-'Mar26'!I3 -> -14415853 | AL3: =I3/'Mar26'!I3-1 -> -0.025886828 | AN3: Bancário: | AO3: Corporativo | AP3: Caixa
B4: CDB | C4: Debênture | D4: Compromissada | F4: =J4+L4+N4+P4+R4+T4 -> 1 | H4: ARX Denali | I4: 1607596557 | J4: 0.35 | K4: 5.6265879e+08 | L4: 0.24 | M4: 3.8582317e+08 | N4: 0.26 | O4: 4.179751e+08 | P4: 0.15 | Q4: 2.4113948e+08 | R4: 0 | S4: 0 | T4: 0 | U4: =+T4*$I4 -> 0 | Y4: =K4-'Mar26'!K4 -> -20177685 | Z4: =M4-'Mar26'!M4 -> -21062671 | AA4: =O4-'Mar26'!O4 -> -5406111.7 | AB4: =Q4-'Mar26'!Q4 -> 4705817.2 | AC4: =+S4-'Mar26'!S4 -> 0 | AE4: =J4-'Mar26'!J4 -> -0.0033333333 | AF4: =L4-'Mar26'!L4 -> -0.0066666667 | AG4: =N4-'Mar26'!N4 -> 0.0033333333 | AH4: =P4-'Mar26'!P4 -> 0.0066666667 | AI4: =R4-'Mar26'!R4 -> 0 | AK4: =I4-'Mar26'!I4 -> -41940650 | AL4: =I4/'Mar26'!I4-1 -> -0.025425707 | AN4: CDB | AO4: Debênture | AP4: Compromissada
B5: LF | C5: CRI | D5: Título Público | F5: =J5+L5+N5+P5+R5+T5 -> 1 | H5: Capitania Top | I5: 2.0536276e+08 | J5: 0.45 | K5: =+J5*$I5 -> 92413242 | L5: 0 | M5: =+L5*$I5 -> 0 | N5: 0.39 | O5: =+N5*$I5 -> 80091476 | P5: 0.04 | Q5: =+P5*$I5 -> 8214510.4 | R5: 0.12 | S5: =+R5*$I5 -> 24643531 | T5: 0 | U5: =+T5*$I5 -> 0 | Y5: =K5-'Mar26'!K5 -> -18375939 | Z5: =M5-'Mar26'!M5 -> 0 | AA5: =O5-'Mar26'!O5 -> 9019171.4 | AB5: =Q5-'Mar26'!Q5 -> 1943424.7 | AC5: =+S5-'Mar26'!S5 -> 3739912.1 | AE5: =J5-'Mar26'!J5 -> -0.08 | AF5: =L5-'Mar26'!L5 -> 0 | AG5: =N5-'Mar26'!N5 -> 0.05 | AH5: =P5-'Mar26'!P5 -> 0.01 | AI5: =R5-'Mar26'!R5 -> 0.02 | AK5: =I5-'Mar26'!I5 -> -3673431 | AL5: =I5/'Mar26'!I5-1 -> -0.017573182 | AN5: LF | AO5: CRI | AP5: Título Público
B6: LFSN | C6: CRA | F6: =J6+L6+N6+P6+R6+T6 -> 1 | H6: Riza Lotus | I6: 3815745000 | J6: 0.256 | K6: =+J6*$I6 -> 976830720 | L6: 0.265 | M6: =+L6*$I6 -> 1011172425 | N6: 0.384 | O6: =+N6*$I6 -> 1465246080 | P6: 0.072 | Q6: =+P6*$I6 -> 274733640 | R6: 0 | S6: =+R6*$I6 -> 0 | T6: 0.023 | U6: =+T6*$I6 -> 87762135 | Y6: =K6-'Mar26'!K6 -> 79384042 | Z6: =M6-'Mar26'!M6 -> -9.571214e+08 | AA6: =O6-'Mar26'!O6 -> 1.3760741e+08 | AB6: =Q6-'Mar26'!Q6 -> 2.5355496e+08 | AC6: =+S6-'Mar26'!S6 -> 4.2357365e+08 | AE6: =J6-'Mar26'!J6 -> 0.038 | AF6: =L6-'Mar26'!L6 -> -0.024666667 | AG6: =N6-'Mar26'!N6 -> -0.013666667 | AH6: =P6-'Mar26'!P6 -> 0.0026666667 | AI6: =R6-'Mar26'!R6 -> 0 | AK6: =I6-'Mar26'!I6 -> -155258000 | AL6: =I6/'Mar26'!I6-1 -> -0.039097931 | AN6: LFSN | AO6: CRA
B7: LFSC | C7: Nota Promissória | F7: =J7+L7+N7+P7+R7+T7 -> 1 | H7: Western Asset Total | I7: 3644190000 | J7: 0.225 | K7: =+J7*$I7 -> 819942750 | L7: 0.309 | M7: =+L7*$I7 -> 1126054710 | N7: 0.308 | O7: =+N7*$I7 -> 1122410520 | P7: 0.158 | Q7: =+P7*$I7 -> 575782020 | R7: 0 | S7: =+R7*$I7 -> 0 | T7: 0 | U7: =+T7*$I7 -> 0 | Y7: =K7-'Mar26'!K7 -> -81096530 | Z7: =M7-'Mar26'!M7 -> -140060830 | AA7: =O7-'Mar26'!O7 -> -66029220 | AB7: =Q7-'Mar26'!Q7 -> 47586580 | AC7: =+S7-'Mar26'!S7 -> 0 | AE7: =J7-'Mar26'!J7 -> -0.007 | AF7: =L7-'Mar26'!L7 -> -0.017 | AG7: =N7-'Mar26'!N7 -> 0.002 | AH7: =P7-'Mar26'!P7 -> 0.022 | AI7: =R7-'Mar26'!R7 -> 0 | AK7: =I7-'Mar26'!I7 -> -239600000 | AL7: =I7/'Mar26'!I7-1 -> -0.061692316 | AN7: LFSC | AO7: Nota Promissória
B8: DPGE | F8: =J8+L8+N8+P8+R8+T8 -> 1 | H8: Daycoval Classic | I8: 2.4429551e+08 | J8: 0.13 | K8: =+J8*$I8 -> 31758417 | L8: 0.4 | M8: =+L8*$I8 -> 97718205 | N8: 0.25 | O8: =+N8*$I8 -> 61073878 | P8: 0.09 | Q8: =+P8*$I8 -> 21986596 | R8: 0 | S8: =+R8*$I8 -> 0 | T8: 0.13 | U8: =+T8*$I8 -> 31758417 | Y8: =K8-'Mar26'!K8 -> -7653.1325 | Z8: =M8-'Mar26'!M8 -> -12241267 | AA8: =O8-'Mar26'!O8 -> 7315913.9 | AB8: =Q8-'Mar26'!Q8 -> 2438245.5 | AC8: =+S8-'Mar26'!S8 -> 0 | AE8: =J8-'Mar26'!J8 -> 0 | AF8: =L8-'Mar26'!L8 -> -0.05 | AG8: =N8-'Mar26'!N8 -> 0.03 | AH8: =P8-'Mar26'!P8 -> 0.01 | AI8: =R8-'Mar26'!R8 -> 0 | AK8: =I8-'Mar26'!I8 -> -58870.25 | AL8: =I8/'Mar26'!I8-1 -> -0.00024092161 | AN8: DPGE
F9: =J9+L9+N9+P9+R9+T9 -> 1 | H9: Iridium Apollo | I9: 1396112809 | J9: 0.5834 | K9: =+J9*$I9 -> 8.1449221e+08 | L9: 0.1777 | M9: =+L9*$I9 -> 2.4808925e+08 | N9: 0.176 | O9: =+N9*$I9 -> 2.4571585e+08 | P9: 0.0507 | Q9: =+P9*$I9 -> 70782919 | R9: 0 | S9: =+R9*$I9 -> 0 | T9: 0.0122 | U9: =+T9*$I9 -> 17032576 | Y9: =K9-'Mar26'!K9 -> -39611308 | Z9: =M9-'Mar26'!M9 -> 2729640 | AA9: =O9-'Mar26'!O9 -> 1215651.4 | AB9: =Q9-'Mar26'!Q9 -> -547544.01 | AC9: =+S9-'Mar26'!S9 -> 0 | AE9: =J9-'Mar26'!J9 -> -0.0129 | AF9: =L9-'Mar26'!L9 -> 0.0064 | AG9: =N9-'Mar26'!N9 -> 0.0053 | AH9: =P9-'Mar26'!P9 -> 0.0009 | AI9: =R9-'Mar26'!R9 -> 0 | AK9: =I9-'Mar26'!I9 -> -36225814 | AL9: =I9/'Mar26'!I9-1 -> -0.025291376
F10: =J10+L10+N10+P10+R10+T10 -> 1 | H10: Porto Seguro FIRF | I10: 6.908158e+09 | J10: 0.312 | K10: =+J10*$I10 -> 2.1553453e+09 | L10: 0.361 | M10: =+L10*$I10 -> 2.493845e+09 | N10: =24.7%+1.6% -> 0.263 | O10: =+N10*$I10 -> 1.8168455e+09 | P10: 0.064 | Q10: =+P10*$I10 -> 4.4212211e+08 | R10: 0 | S10: =+R10*$I10 -> 0 | T10: 0 | U10: =+T10*$I10 -> 0 | Y10: =K10-'Mar26'!K10 -> -6.0949075e+08 | Z10: =M10-'Mar26'!M10 -> -2.1022538e+08 | AA10: =O10-'Mar26'!O10 -> 1.0781228e+08 | AB10: =Q10-'Mar26'!Q10 -> 24358424 | AC10: =+S10-'Mar26'!S10 -> 0 | AE10: =J10-'Mar26'!J10 -> -0.052 | AF10: =L10-'Mar26'!L10 -> 0.005 | AG10: =N10-'Mar26'!N10 -> 0.038 | AH10: =P10-'Mar26'!P10 -> 0.009 | AI10: =R10-'Mar26'!R10 -> 0 | AK10: =I10-'Mar26'!I10 -> -6.8754542e+08 | AL10: =I10/'Mar26'!I10-1 -> -0.090517676
F11: =J11+L11+N11+P11+R11+T11 -> 1 | H11: Nu Reserva Imediata | I11: 2.8368773e+09 | J11: 0.59 | K11: =+J11*$I11 -> 1.6737576e+09 | L11: 0.3 | M11: =+L11*$I11 -> 8.5106319e+08 | N11: 0.11 | O11: =+N11*$I11 -> 3.120565e+08 | P11: 0 | Q11: =+P11*$I11 -> 0 | R11: 0 | S11: =+R11*$I11 -> 0 | T11: 0 | U11: =+T11*$I11 -> 0 | Y11: =K11-'Mar26'!K11 -> -1.0289974e+08 | Z11: =M11-'Mar26'!M11 -> 77357571 | AA11: =O11-'Mar26'!O11 -> -3156897.5 | AB11: =Q11-'Mar26'!Q11 -> 0 | AC11: =+S11-'Mar26'!S11 -> 0 | AE11: =J11-'Mar26'!J11 -> -0.03 | AF11: =L11-'Mar26'!L11 -> 0.03 | AG11: =N11-'Mar26'!N11 -> 0 | AH11: =P11-'Mar26'!P11 -> 0 | AI11: =R11-'Mar26'!R11 -> 0 | AK11: =I11-'Mar26'!I11 -> -28699068 | AL11: =I11/'Mar26'!I11-1 -> -0.010015112
B12: Pegar fora da XP: | F12: =J12+L12+N12+P12+R12+T12 -> 1 | H12: Inter Conservador | I12: 1315550000 | J12: 0.304 | K12: =+J12*$I12 -> 399927200 | L12: 0.488 | M12: =+L12*$I12 -> 641988400 | N12: 0.176 | O12: =+N12*$I12 -> 231536800 | P12: 0.032 | Q12: =+P12*$I12 -> 42097600 | R12: 0 | S12: =+R12*$I12 -> 0 | T12: 0 | U12: =+T12*$I12 -> 0 | Y12: =K12-'Mar26'!K12 -> 51099950 | Z12: =M12-'Mar26'!M12 -> -23701850 | AA12: =O12-'Mar26'!O12 -> -108951950 | AB12: =Q12-'Mar26'!Q12 -> 7353850 | AC12: =+S12-'Mar26'!S12 -> 0 | AE12: =J12-'Mar26'!J12 -> 0.053 | AF12: =L12-'Mar26'!L12 -> 0.009 | AG12: =N12-'Mar26'!N12 -> -0.069 | AH12: =P12-'Mar26'!P12 -> 0.007 | AI12: =R12-'Mar26'!R12 -> 0 | AK12: =I12-'Mar26'!I12 -> -74200000 | AL12: =I12/'Mar26'!I12-1 -> -0.053390898
B13: NU Reserva Imediata | F13: =J13+L13+N13+P13+R13+T13 -> 1.01 | H13: Absolute Atenas | I13: 745900000 | J13: 0.42 | K13: =+J13*$I13 -> 313278000 | L13: 0.34 | M13: =+L13*$I13 -> 2.53606e+08 | N13: 0.13 | O13: =+N13*$I13 -> 96967000 | P13: 0.12 | Q13: =+P13*$I13 -> 89508000 | R13: 0 | S13: =+R13*$I13 -> 0 | T13: 0 | U13: =+T13*$I13 -> 0 | Y13: =K13-'Mar26'!K13 -> 265992000 | Z13: =M13-'Mar26'!M13 -> -2.11373e+08 | AA13: =O13-'Mar26'!O13 -> -60653000 | AB13: =Q13-'Mar26'!Q13 -> -28707000 | AC13: =+S13-'Mar26'!S13 -> 0 | AE13: =J13-'Mar26'!J13 -> 0.36 | AF13: =L13-'Mar26'!L13 -> -0.25 | AG13: =N13-'Mar26'!N13 -> -0.07 | AH13: =P13-'Mar26'!P13 -> -0.03 | AI13: =R13-'Mar26'!R13 -> 0 | AK13: =I13-'Mar26'!I13 -> -42200000 | AL13: =I13/'Mar26'!I13-1 -> -0.053546504
B14: JGP Select | F14: =J14+L14+N14+P14+R14+T14 -> 1.0003206 | H14: TOTAL | I14: =SUM(I3:I13) -> 2.3262252e+10 | J14: =K14/$I$14 -> 0.35012165 | K14: =SUM(K3:K13) -> 8.144618e+09 | L14: =M14/$I$14 -> 0.31075284 | M14: =SUM(M3:M13) -> 7.2288109e+09 | N14: =O14/$I$14 -> 0.25556013 | O14: =SUM(O3:O13) -> 5.9449042e+09 | P14: =Q14/$I$14 -> 0.076972805 | Q14: =SUM(Q3:Q13) -> 1.7905608e+09 | R14: =S14/$I$14 -> 0.0010593786 | S14: =SUM(S3:S13) -> 24643531 | T14: =U14/$I$14 -> 0.0058538358 | U14: =SUM(U3:U13) -> 1.361734e+08 | Y14: =K14-'Mar26'!K14 -> -4.7719803e+08 | Z14: =M14-'Mar26'!M14 -> -1.500043e+09 | AA14: =O14-'Mar26'!O14 -> 14355644 | AB14: =Q14-'Mar26'!Q14 -> 3.0864684e+08 | AC14: =+S14-'Mar26'!S14 -> 4.2731357e+08 | AE14: =J14-'Mar26'!J14 -> -0.0005572668 | AF14: =L14-'Mar26'!L14 -> -0.044279672 | AG14: =N14-'Mar26'!N14 -> 0.014344323 | AH14: =P14-'Mar26'!P14 -> 0.016698267 | AI14: =R14-'Mar26'!R14 -> 0.017437354 | AK14: =I14-'Mar26'!I14 -> -1.3238171e+09 | AL14: =I14/'Mar26'!I14-1 -> -0.053844195
B15: Absolute Olimpia
H16: Fundo D+30 | I16: PL | J16: Caixa | L16: Bancários | N16: Corporativo | P16: FIDC | R16: FII | T16: Outros | Y16: Δ Caixa | Z16: Δ Bancários | AA16: Δ Corporativo | AB16: Δ FIDC | AC16: Δ FII | AE16: Δ Caixa | AF16: Δ Bancários | AG16: Δ Corporativo | AH16: Δ FIDC | AI16: Δ FII
F17: =J17+L17+N17+P17+R17+T17 -> 1 | H17: Geraes 30 | I17: 3.146219e+08 | J17: 0.3282 | K17: =+J17*$I17 -> 1.0325891e+08 | L17: 0.2728 | M17: =+L17*$I17 -> 85828853 | N17: 0.2603 | O17: =+N17*$I17 -> 81896080 | P17: 0.0721 | Q17: =+P17*$I17 -> 22684239 | R17: 0 | S17: =+R17*$I17 -> 0 | T17: 0.0666 | U17: =+T17*$I17 -> 20953818 | Y17: =K17-'Mar26'!K17 -> -2668364.3 | Z17: =M17-'Mar26'!M17 -> 642586.66 | AA17: =O17-'Mar26'!O17 -> -3644458.9 | AB17: =Q17-'Mar26'!Q17 -> -1857135.6 | AC17: =+S17-'Mar26'!S17 -> 0 | AE17: =J17-'Mar26'!J17 -> -0.0007 | AF17: =L17-'Mar26'!L17 -> 0.0083 | AG17: =N17-'Mar26'!N17 -> -0.0053 | AH17: =P17-'Mar26'!P17 -> -0.0041 | AI17: =R17-'Mar26'!R17 -> 0 | AK17: =I17-'Mar26'!I17 -> -7443384.1 | AL17: =I17/'Mar26'!I17-1 -> -0.023111414
F18: =J18+L18+N18+P18+R18+T18 -> 1 | H18: Daycoval Classic 30 | I18: 8.6197301e+08 | J18: 0.07 | K18: =+J18*$I18 -> 60338111 | L18: 0.25 | M18: =+L18*$I18 -> 2.1549325e+08 | N18: 0.38 | O18: =+N18*$I18 -> 3.2754974e+08 | P18: 0.18 | Q18: =+P18*$I18 -> 1.5515514e+08 | R18: 0 | S18: =+R18*$I18 -> 0 | T18: 0.12 | U18: =+T18*$I18 -> 1.0343676e+08 | Y18: =K18-'Mar26'!K18 -> -8559112.1 | Z18: =M18-'Mar26'!M18 -> 189431.41 | AA18: =O18-'Mar26'!O18 -> 287935.75 | AB18: =Q18-'Mar26'!Q18 -> 8748543.5 | AC18: =+S18-'Mar26'!S18 -> 0 | AE18: =J18-'Mar26'!J18 -> -0.01 | AF18: =L18-'Mar26'!L18 -> 0 | AG18: =N18-'Mar26'!N18 -> 0 | AH18: =P18-'Mar26'!P18 -> 0.01 | AI18: =R18-'Mar26'!R18 -> 0 | AK18: =I18-'Mar26'!I18 -> 757725.66 | AL18: =I18/'Mar26'!I18-1 -> 0.00087983303
F19: =J19+L19+N19+P19+R19+T19 -> 1 | H19: Riza Lotus Plus | I19: 506423347 | J19: 0.18 | K19: =+J19*$I19 -> 91156202 | L19: 0.185 | M19: =+L19*$I19 -> 93688319 | N19: =43.9%+2.8%+5.1% -> 0.518 | O19: =+N19*$I19 -> 2.6232729e+08 | P19: 0.09 | Q19: =+P19*$I19 -> 45578101 | R19: 0 | S19: =+R19*$I19 -> 0 | T19: 0.027 | U19: =+T19*$I19 -> 13673430 | Y19: =K19-'Mar26'!K19 -> 9562547.4 | Z19: =M19-'Mar26'!M19 -> -4750477.6 | AA19: =O19-'Mar26'!O19 -> -20355240 | AB19: =Q19-'Mar26'!Q19 -> -2325270.5 | AC19: =+S19-'Mar26'!S19 -> 0 | AE19: =J19-'Mar26'!J19 -> 0.025 | AF19: =L19-'Mar26'!L19 -> -0.002 | AG19: =N19-'Mar26'!N19 -> -0.019 | AH19: =P19-'Mar26'!P19 -> -0.001 | AI19: =R19-'Mar26'!R19 -> 0 | AK19: =I19-'Mar26'!I19 -> -19987331 | AL19: =I19/'Mar26'!I19-1 -> -0.037969084
C20: LEGENDA: | F20: =J20+L20+N20+P20+R20+T20 -> 1 | H20: ARX Vinson Advisory | I20: 1264902157 | J20: 0.23 | K20: =+J20*$I20 -> 2.909275e+08 | L20: 0.25 | M20: =+L20*$I20 -> 3.1622554e+08 | N20: 0.34 | O20: =+N20*$I20 -> 4.3006673e+08 | P20: 0.18 | Q20: =+P20*$I20 -> 2.2768239e+08 | R20: 0 | S20: =+R20*$I20 -> 0 | T20: 0 | U20: =+T20*$I20 -> 0 | Y20: =K20-'Mar26'!K20 -> 19611553 | Z20: =M20-'Mar26'!M20 -> -97208278 | AA20: =O20-'Mar26'!O20 -> 55392336 | AB20: =Q20-'Mar26'!Q20 -> -4874134.1 | AC20: =+S20-'Mar26'!S20 -> 0 | AE20: =J20-'Mar26'!J20 -> 0.02 | AF20: =L20-'Mar26'!L20 -> -0.07 | AG20: =N20-'Mar26'!N20 -> 0.05 | AH20: =P20-'Mar26'!P20 -> 0 | AI20: =R20-'Mar26'!R20 -> 0 | AK20: =I20-'Mar26'!I20 -> -27078523 | AL20: =I20/'Mar26'!I20-1 -> -0.020958923
B21: Bancário: | C21: Corporativo | D21: Caixa | F21: =J21+L21+N21+P21+R21+T21 -> 1 | H21: Sparta Max Advisory | I21: 145000000 | J21: 0.19 | K21: =+J21*$I21 -> 27550000 | L21: 0.17 | M21: =+L21*$I21 -> 24650000 | N21: 0.51 | O21: =+N21*$I21 -> 73950000 | P21: 0.13 | Q21: =+P21*$I21 -> 18850000 | R21: 0 | S21: =+R21*$I21 -> 0 | T21: 0 | U21: =+T21*$I21 -> 0 | Y21: =K21-'Mar26'!K21 -> -2300000 | Z21: =M21-'Mar26'!M21 -> -722500 | AA21: =O21-'Mar26'!O21 -> -3660000 | AB21: =Q21-'Mar26'!Q21 -> 940000 | AC21: =+S21-'Mar26'!S21 -> 0 | AE21: =J21-'Mar26'!J21 -> -0.01 | AF21: =L21-'Mar26'!L21 -> 0 | AG21: =N21-'Mar26'!N21 -> -0.01 | AH21: =P21-'Mar26'!P21 -> 0.01 | AI21: =R21-'Mar26'!R21 -> 0 | AK21: =I21-'Mar26'!I21 -> -4250000 | AL21: =I21/'Mar26'!I21-1 -> -0.028475712
B22: CDB | C22: Debênture | D22: Compromissada | F22: =J22+L22+N22+P22+R22+T22 -> 1 | H22: Polo Crédito Corporativo | I22: 1189700000 | J22: 0.17 | K22: =+J22*$I22 -> 202249000 | L22: 0.31 | M22: =+L22*$I22 -> 368807000 | N22: 0.47 | O22: =+N22*$I22 -> 559159000 | P22: 0.05 | Q22: =+P22*$I22 -> 59485000 | R22: 0 | S22: =+R22*$I22 -> 0 | T22: 0 | U22: =+T22*$I22 -> 0 | Y22: =K22-'Mar26'!K22 -> 1577000 | Z22: =M22-'Mar26'!M22 -> -32537000 | AA22: =O22-'Mar26'!O22 -> -42857000 | AB22: =Q22-'Mar26'!Q22 -> 9317000 | AC22: =+S22-'Mar26'!S22 -> 0 | AE22: =J22-'Mar26'!J22 -> 0.01 | AF22: =L22-'Mar26'!L22 -> -0.01 | AG22: =N22-'Mar26'!N22 -> -0.01 | AH22: =P22-'Mar26'!P22 -> 0.01 | AI22: =R22-'Mar26'!R22 -> 0 | AK22: =I22-'Mar26'!I22 -> -64500000 | AL22: =I22/'Mar26'!I22-1 -> -0.051427205
B23: LF | C23: CRI | D23: Título Público | F23: =J23+L23+N23+P23+R23+T23 -> 1 | H23: Iridium Titan Advisory | I23: 196563310 | J23: 0.4596 | K23: =+J23*$I23 -> 90340497 | L23: 0.1374 | M23: =+L23*$I23 -> 27007799 | N23: 0.2827 | O23: =+N23*$I23 -> 55568448 | P23: 0.1082 | Q23: =+P23*$I23 -> 21268150 | R23: 0 | S23: =+R23*$I23 -> 0 | T23: 0.0121 | U23: =+T23*$I23 -> 2378416.1 | Y23: =K23-'Mar26'!K23 -> -11008757 | Z23: =M23-'Mar26'!M23 -> 270860.97 | AA23: =O23-'Mar26'!O23 -> 1662335.2 | AB23: =Q23-'Mar26'!Q23 -> 47378.091 | AC23: =+S23-'Mar26'!S23 -> 0 | AE23: =J23-'Mar26'!J23 -> -0.0328 | AF23: =L23-'Mar26'!L23 -> 0.0075 | AG23: =N23-'Mar26'!N23 -> 0.0208 | AH23: =P23-'Mar26'!P23 -> 0.0051 | AI23: =R23-'Mar26'!R23 -> 0 | AK23: =I23-'Mar26'!I23 -> -9263771 | AL23: =I23/'Mar26'!I23-1 -> -0.045007542
B24: LFSN | C24: CRA | F24: =J24+L24+N24+P24+R24+T24 -> 1 | H24: Porto Seguro Ipê | I24: 5.3774448e+08 | J24: 0.128 | K24: =+J24*$I24 -> 68831293 | L24: 0.356 | M24: =+L24*$I24 -> 1.9143703e+08 | N24: 0.393 | O24: =+N24*$I24 -> 2.1133358e+08 | P24: 0.123 | Q24: =+P24*$I24 -> 66142571 | R24: 0 | S24: =+R24*$I24 -> 0 | T24: 0 | U24: =+T24*$I24 -> 0 | Y24: =K24-'Mar26'!K24 -> -2685767.8 | Z24: =M24-'Mar26'!M24 -> -30265855 | AA24: =O24-'Mar26'!O24 -> 16587121 | AB24: =Q24-'Mar26'!Q24 -> 3977740.8 | AC24: =+S24-'Mar26'!S24 -> 0 | AE24: =J24-'Mar26'!J24 -> -0.002 | AF24: =L24-'Mar26'!L24 -> -0.047 | AG24: =N24-'Mar26'!N24 -> 0.039 | AH24: =P24-'Mar26'!P24 -> 0.01 | AI24: =R24-'Mar26'!R24 -> 0 | AK24: =I24-'Mar26'!I24 -> -12386760 | AL24: =I24/'Mar26'!I24-1 -> -0.02251601
B25: LFSC | C25: Nota Promissória | F25: =J25+L25+N25+P25+R25+T25 -> 1 | H25: Sparta Top Advisory | I25: 578700000 | J25: 0.2 | K25: =+J25*$I25 -> 115740000 | L25: 0.25 | M25: =+L25*$I25 -> 144675000 | N25: 0.45 | O25: =+N25*$I25 -> 260415000 | P25: 0.1 | Q25: =+P25*$I25 -> 57870000 | R25: 0 | S25: =+R25*$I25 -> 0 | T25: 0 | U25: =+T25*$I25 -> 0 | Y25: =K25-'Mar26'!K25 -> -160000 | Z25: =M25-'Mar26'!M25 -> -7825000 | AA25: =O25-'Mar26'!O25 -> -26285000 | AB25: =Q25-'Mar26'!Q25 -> 2970000 | AC25: =+S25-'Mar26'!S25 -> 0 | AE25: =J25-'Mar26'!J25 -> 0.01 | AF25: =L25-'Mar26'!L25 -> 0 | AG25: =N25-'Mar26'!N25 -> -0.02 | AH25: =P25-'Mar26'!P25 -> 0.01 | AI25: =R25-'Mar26'!R25 -> 0 | AK25: =I25-'Mar26'!I25 -> -31300000 | AL25: =I25/'Mar26'!I25-1 -> -0.051311475
B26: DPGE | F26: =J26+L26+N26+P26+R26+T26 -> 1 | H26: Absolute Creta | I26: 1786800000 | J26: 0.17 | K26: =+J26*$I26 -> 303756000 | L26: 0.21 | M26: =+L26*$I26 -> 375228000 | N26: 0.46 | O26: =+N26*$I26 -> 821928000 | P26: 0.16 | Q26: =+P26*$I26 -> 285888000 | R26: 0 | S26: =+R26*$I26 -> 0 | T26: 0 | U26: =+T26*$I26 -> 0 | Y26: =K26-'Mar26'!K26 -> -99258150 | Z26: =M26-'Mar26'!M26 -> -85359600 | AA26: =O26-'Mar26'!O26 -> -22482600 | AB26: =Q26-'Mar26'!Q26 -> 74785350 | AC26: =+S26-'Mar26'!S26 -> 0 | AE26: =J26-'Mar26'!J26 -> -0.04 | AF26: =L26-'Mar26'!L26 -> -0.03 | AG26: =N26-'Mar26'!N26 -> 0.02 | AH26: =P26-'Mar26'!P26 -> 0.05 | AI26: =R26-'Mar26'!R26 -> 0 | AK26: =I26-'Mar26'!I26 -> -132315000 | AL26: =I26/'Mar26'!I26-1 -> -0.068945842
F27: =J27+L27+N27+P27+R27+T27 -> 1 | H27: TOTAL | I27: =SUM(I17:I26) -> 7.3824282e+09 | J27: =K27/$I$27 -> 0.18342847 | K27: =SUM(K17:K26) -> 1.3541475e+09 | L27: =M27/$I$27 -> 0.24965238 | M27: =SUM(M17:M26) -> 1.8430408e+09 | N27: =O27/$I$27 -> 0.41777499 | O27: =SUM(O17:O26) -> 3.0841939e+09 | P27: =Q27/$I$27 -> 0.13012028 | Q27: =SUM(Q17:Q26) -> 9.6060359e+08 | R27: =S27/$I$27 -> 0 | S27: =SUM(S17:S26) -> 0 | T27: =U27/$I$27 -> 0.01902388 | U27: =SUM(U17:U26) -> 1.4044243e+08 | Y27: =K27-'Mar26'!K27 -> -95889051 | Z27: =M27-'Mar26'!M27 -> -2.5756583e+08 | AA27: =O27-'Mar26'!O27 -> -45354571 | AB27: =Q27-'Mar26'!Q27 -> 91729472 | AC27: =+S27-'Mar26'!S27 -> 0 | AE27: =J27-'Mar26'!J27 -> -0.005128064 | AF27: =L27-'Mar26'!L27 -> -0.023501491 | AG27: =N27-'Mar26'!N27 -> 0.010821936 | AH27: =P27-'Mar26'!P27 -> 0.017135612 | AI27: =R27-'Mar26'!R27 -> 0 | AK27: =I27-'Mar26'!I27 -> -3.0776704e+08 | AL27: =I27/'Mar26'!I27-1 -> -0.040020706
H29: Fundo D+60 | I29: PL | J29: Caixa | L29: Bancários | N29: Corporativo | P29: FIDC | R29: Bonds | T29: Outros | Y29: Δ Caixa | Z29: Δ Bancários | AA29: Δ Corporativo | AB29: Δ FIDC | AC29: Δ Bonds | AE29: Δ Caixa | AF29: Δ Bancários | AG29: Δ Corporativo | AH29: Δ FIDC | AI29: Δ Bonds
F30: =J30+L30+N30+P30+R30+T30 -> 1 | H30: Horizonte | I30: 2.2967051e+08 | J30: =0.2063+0.0141 -> 0.2204 | K30: =+J30*$I30 -> 50619380 | L30: =0.0847+0.0739+0.0306 -> 0.1892 | M30: =+L30*$I30 -> 43453660 | N30: =0.3336+0.0186+0.0107 -> 0.3629 | O30: =+N30*$I30 -> 83347428 | P30: 0.1532 | Q30: =+P30*$I30 -> 35185522 | R30: 0.0501 | S30: =+R30*$I30 -> 11506493 | T30: 0.0242 | U30: =+T30*$I30 -> 5558026.3 | Y30: =K30-'Mar26'!K30 -> 9882193.7 | Z30: =M30-'Mar26'!M30 -> -623384.79 | AA30: =O30-'Mar26'!O30 -> -5647307.2 | AB30: =Q30-'Mar26'!Q30 -> -326035.48 | AC30: =+S30-'Mar26'!S30 -> -785095.85 | AE30: =J30-'Mar26'!J30 -> 0.0411 | AF30: =L30-'Mar26'!L30 -> -0.0048 | AG30: =N30-'Mar26'!N30 -> -0.0288 | AH30: =P30-'Mar26'!P30 -> -0.0031 | AI30: =R30-'Mar26'!R30 -> -0.004 | AK30: =I30-'Mar26'!I30 -> 2469245.6 | AL30: =I30/'Mar26'!I30-1 -> 0.010868098
F31: =J31+L31+N31+P31+R31+T31 -> 0 | H31: BTG PACTUAL CRED PLUS | K31: =+J31*$I31 -> 0 | M31: =+L31*$I31 -> 0 | O31: =+N31*$I31 -> 0 | Q31: =+P31*$I31 -> 0 | S31: =+R31*$I31 -> 0 | U31: =+T31*$I31 -> 0 | Y31: =K31-'Mar26'!K31 -> 0 | Z31: =M31-'Mar26'!M31 -> 0 | AA31: =O31-'Mar26'!O31 -> 0 | AB31: =Q31-'Mar26'!Q31 -> 0 | AC31: =+S31-'Mar26'!S31 -> 0 | AE31: =J31-'Mar26'!J31 -> 0 | AF31: =L31-'Mar26'!L31 -> 0 | AG31: =N31-'Mar26'!N31 -> 0 | AH31: =P31-'Mar26'!P31 -> 0 | AI31: =R31-'Mar26'!R31 -> 0 | AK31: =I31-'Mar26'!I31 -> 0 | AL31: =I31/'Mar26'!I31-1 -> #DIV/0!
F32: =J32+L32+N32+P32+R32+T32 -> 1 | H32: JGP Select | I32: 345450326 | J32: 0.08 | K32: =+J32*$I32 -> 27636026 | L32: 0.09 | M32: =+L32*$I32 -> 31090529 | N32: 0.5 | O32: =+N32*$I32 -> 172725163 | P32: 0.08 | Q32: =+P32*$I32 -> 27636026 | R32: 0.14 | S32: =+R32*$I32 -> 48363046 | T32: 0.11 | U32: =+T32*$I32 -> 37999536 | Y32: =K32-'Mar26'!K32 -> 5013647.6 | Z32: =M32-'Mar26'!M32 -> -4458922.6 | AA32: =O32-'Mar26'!O32 -> 11136745 | AB32: =Q32-'Mar26'!Q32 -> 1781879.2 | AC32: =+S32-'Mar26'!S32 -> -9808784.8 | AE32: =J32-'Mar26'!J32 -> 0.01 | AF32: =L32-'Mar26'!L32 -> -0.02 | AG32: =N32-'Mar26'!N32 -> 0 | AH32: =P32-'Mar26'!P32 -> 0 | AI32: =R32-'Mar26'!R32 -> -0.04 | AK32: =I32-'Mar26'!I32 -> 22273490 | AL32: =I32/'Mar26'!I32-1 -> 0.068920441
F33: =J33+L33+N33+P33+R33+T33 -> 1 | H33: ARX Everest Advisory | I33: 433497135 | J33: 0.2 | K33: =+J33*$I33 -> 86699427 | L33: 0.17 | M33: =+L33*$I33 -> 73694513 | N33: 0.42 | O33: =+N33*$I33 -> 1.820688e+08 | P33: 0.18 | Q33: =+P33*$I33 -> 78029484 | R33: 0 | S33: =+R33*$I33 -> 0 | T33: 0.03 | U33: =+T33*$I33 -> 13004914 | Y33: =K33-'Mar26'!K33 -> -8185472.8 | Z33: =M33-'Mar26'!M33 -> -21190387 | AA33: =O33-'Mar26'!O33 -> 1335654.3 | AB33: =Q33-'Mar26'!Q33 -> -3300429.8 | AC33: =+S33-'Mar26'!S33 -> 0 | AE33: =J33-'Mar26'!J33 -> -0.01 | AF33: =L33-'Mar26'!L33 -> -0.04 | AG33: =N33-'Mar26'!N33 -> 0.02 | AH33: =P33-'Mar26'!P33 -> 0 | AI33: =R33-'Mar26'!R33 -> 0 | AK33: =I33-'Mar26'!I33 -> -18335721 | AL33: =I33/'Mar26'!I33-1 -> -0.040580761
F34: =J34+L34+N34+P34+R34+T34 -> 1 | H34: Polo Total | I34: 77600000 | J34: 0.15 | K34: =+J34*$I34 -> 11640000 | L34: 0.21 | M34: =+L34*$I34 -> 16296000 | N34: 0.49 | O34: =+N34*$I34 -> 38024000 | P34: 0.04 | Q34: =+P34*$I34 -> 3104000 | R34: 0.11 | S34: =+R34*$I34 -> 8536000 | T34: 0 | U34: =+T34*$I34 -> 0 | Y34: =K34-'Mar26'!K34 -> 8516000 | Z34: =M34-'Mar26'!M34 -> -4010000 | AA34: =O34-'Mar26'!O34 -> 536000 | AB34: =Q34-'Mar26'!Q34 -> -20000 | AC34: =+S34-'Mar26'!S34 -> -5522000 | AE34: =J34-'Mar26'!J34 -> 0.11 | AF34: =L34-'Mar26'!L34 -> -0.05 | AG34: =N34-'Mar26'!N34 -> 0.01 | AH34: =P34-'Mar26'!P34 -> 0 | AI34: =R34-'Mar26'!R34 -> -0.07 | AK34: =I34-'Mar26'!I34 -> -500000 | AL34: =I34/'Mar26'!I34-1 -> -0.0064020487
F35: =J35+L35+N35+P35+R35+T35 -> 1 | H35: Absolute Olimpia | I35: 278500000 | J35: 0.02 | K35: =+J35*$I35 -> 5570000 | L35: 0 | M35: =+L35*$I35 -> 0 | N35: 0.38 | O35: =+N35*$I35 -> 105830000 | P35: 0.55 | Q35: =+P35*$I35 -> 153175000 | R35: 0.05 | S35: =+R35*$I35 -> 13925000 | T35: 0 | U35: =+T35*$I35 -> 0 | Y35: =K35-'Mar26'!K35 -> -11728520 | Z35: =M35-'Mar26'!M35 -> -3052680 | AA35: =O35-'Mar26'!O35 -> -24417680 | AB35: =Q35-'Mar26'!Q35 -> 24962440 | AC35: =+S35-'Mar26'!S35 -> -12531560 | AE35: =J35-'Mar26'!J35 -> -0.036666667 | AF35: =L35-'Mar26'!L35 -> -0.01 | AG35: =N35-'Mar26'!N35 -> -0.046666667 | AH35: =P35-'Mar26'!P35 -> 0.13 | AI35: =R35-'Mar26'!R35 -> -0.036666667 | AK35: =I35-'Mar26'!I35 -> -26768000 | AL35: =I35/'Mar26'!I35-1 -> -0.087686885
F36: =J36+L36+N36+P36+R36+T36 -> 1 | H36: TOTAL | I36: =SUM(I30:I35) -> 1.364718e+09 | J36: =+K36/$I$36 -> 0.13348167 | K36: =SUM(K30:K35) -> 1.8216483e+08 | L36: =+M36/$I$36 -> 0.12056315 | M36: =SUM(M30:M35) -> 1.645347e+08 | N36: =+O36/$I$36 -> 0.42645836 | O36: =SUM(O30:O35) -> 5.8199539e+08 | P36: =+Q36/$I$36 -> 0.21772266 | Q36: =SUM(Q30:Q35) -> 2.9713003e+08 | R36: =+S36/$I$36 -> 0.060327877 | S36: =SUM(S30:S35) -> 82330538 | T36: =+U36/$I$36 -> 0.041446275 | U36: =SUM(U30:U35) -> 56562476 | Y36: =K36-'Mar26'!K36 -> 3497848.5 | Z36: =M36-'Mar26'!M36 -> -33335374 | AA36: =O36-'Mar26'!O36 -> -17056588 | AB36: =Q36-'Mar26'!Q36 -> 23097854 | AC36: =+S36-'Mar26'!S36 -> -28647441 | AE36: =J36-'Mar26'!J36 -> 0.004534139 | AF36: =L36-'Mar26'!L36 -> -0.022243632 | AG36: =N36-'Mar26'!N36 -> -0.0058894127 | AH36: =P36-'Mar26'!P36 -> 0.019948169 | AI36: =R36-'Mar26'!R36 -> -0.019767146 | AK36: =I36-'Mar26'!I36 -> -20860985 | AL36: =I36/'Mar26'!I36-1 -> -0.01505579
J40: =J6-'Jan26'!J6 -> 0.114 | K40: =K6-'Jan26'!K6 -> 4.0656982e+08 | L40: =L6-'Jan26'!L6 -> -0.074 | M40: =M6-'Jan26'!M6 -> -3.5022507e+08 | N40: =N6-'Jan26'!N6 -> -0.041 | O40: =O6-'Jan26'!O6 -> -241520685 | P40: =P6-'Jan26'!P6 -> 0.008 | Q40: =Q6-'Jan26'!Q6 -> 17714645 | ... T40: =T6-'Jan26'!T6 -> -0.007
J41: =J40/3 -> 0.038 | K41: =K40/3 -> 1.3552327e+08 | L41: =L40/3 -> -0.024666667 | M41: =M40/3 -> -1.1674169e+08 | N41: =N40/3 -> -0.013666667 | O41: =O40/3 -> -80506895 | P41: =P40/3 -> 0.0026666667 | Q41: =Q40/3 -> 5904881.6 | ... T41: =T40/3 -> -0.0023333333

Sheet Mar26
C2: LEGENDA: | H2: Fundo D+1 | I2: PL | J2: Caixa | L2: Bancários | N2: Corporativo | P2: FIDC | R2: FII | T2: Outros | W2: Obs: | Y2: Δ Caixa | Z2: Δ Bancários | AA2: Δ Corporativo | AB2: Δ FIDC | AC2: Δ FII | AE2: Δ Caixa | AF2: Δ Bancários | AG2: Δ Corporativo | AH2: Δ FIDC | AI2: Δ FII | AK2: Var. PL | AL2: % | AO2: LEGENDA:
B3: Bancário | C3: Corporativo | D3: Caixa | F3: =J3+L3+N3+P3+R3+T3 -> 1 | H3: Geraes | I3: 5.5687986e+08 | J3: =42.06%+12.93% -> 0.5499 | K3: =+J3*$I3 -> 3.0622824e+08 | L3: =8.34%+7.4%+3.58%+2.91% -> 0.2223 | M3: =+L3*$I3 -> 1.2379439e+08 | N3: 0.1785 | O3: =+N3*$I3 -> 99403056 | P3: 0.0507 | Q3: =+P3*$I3 -> 28233809 | R3: 0 | S3: =+R3*$I3 -> 0 | T3: -0.0014 | U3: =+T3*$I3 -> -779631.81 | Y3: =K3-'Fev26'!K3 -> -55430975 | Z3: =M3-'Fev26'!M3 -> 18155504 | AA3: =O3-'Fev26'!O3 -> 9917967.9 | AB3: =Q3-'Fev26'!Q3 -> 4351750 | AC3: =+S3-'Fev26'!S3 -> 0 | AE3: =J3-'Fev26'!J3 -> -0.0725 | AF3: =L3-'Fev26'!L3 -> 0.0405 | AG3: =N3-'Fev26'!N3 -> 0.0245 | AH3: =P3-'Fev26'!P3 -> 0.0096 | AI3: =R3-'Fev26'!R3 -> 0 | AK3: =I3-'Fev26'!I3 -> -24192135 | AL3: =I3/'Fev26'!I3-1 -> -0.041633627 | AN3: Bancário: | AO3: Corporativo | AP3: Caixa
B4: CDB | C4: Debênture | D4: Compromissada | F4: =J4+L4+N4+P4+R4+T4 -> 1 | H4: ARX Denali | I4: 1.6495372e+09 | J4: 0.35333333 | K4: 5.8283648e+08 | L4: 0.24666667 | M4: 4.0688584e+08 | N4: 0.25666667 | O4: 4.2338122e+08 | P4: 0.14333333 | Q4: 2.3643367e+08 | R4: 0 | S4: 0 | T4: 0 | U4: =+T4*$I4 -> 0 | Y4: =K4-'Fev26'!K4 -> -33751377 | Z4: =M4-'Fev26'!M4 -> -31064409 | AA4: =O4-'Fev26'!O4 -> -14569037 | AB4: =Q4-'Fev26'!Q4 -> 171029.72 | AC4: =+S4-'Fev26'!S4 -> 0 | AE4: =J4-'Fev26'!J4 -> -0.0033333333 | AF4: =L4-'Fev26'!L4 -> -0.0066666667 | AG4: =N4-'Fev26'!N4 -> 0.0033333333 | AH4: =P4-'Fev26'!P4 -> 0.0066666667 | AI4: =R4-'Fev26'!R4 -> 0 | AK4: =I4-'Fev26'!I4 -> -79213793 | AL4: =I4/'Fev26'!I4-1 -> -0.045821401 | AN4: CDB | AO4: Debênture | AP4: Compromissada
B5: LF | C5: CRI | D5: Título Público | F5: =J5+L5+N5+P5+R5+T5 -> 1 | H5: Capitania Top | I5: 2.0903619e+08 | J5: 0.53 | K5: =+J5*$I5 -> 1.1078918e+08 | L5: 0 | M5: =+L5*$I5 -> 0 | N5: 0.34 | O5: =+N5*$I5 -> 71072305 | P5: 0.03 | Q5: =+P5*$I5 -> 6271085.7 | R5: 0.1 | S5: =+R5*$I5 -> 20903619 | T5: 0 | U5: =+T5*$I5 -> 0 | Y5: =K5-'Fev26'!K5 -> 8502200.7 | Z5: =M5-'Fev26'!M5 -> 0 | AA5: =O5-'Fev26'!O5 -> -8978375.4 | AB5: =Q5-'Fev26'!Q5 -> -7070694.3 | AC5: =+S5-'Fev26'!S5 -> -5779941 | AE5: =J5-'Fev26'!J5 -> 0.07 | AF5: =L5-'Fev26'!L5 -> 0 | AG5: =N5-'Fev26'!N5 -> -0.02 | AH5: =P5-'Fev26'!P5 -> -0.03 | AI5: =R5-'Fev26'!R5 -> -0.02 | AK5: =I5-'Fev26'!I5 -> -13326810 | AL5: =I5/'Fev26'!I5-1 -> -0.059932678 | AN5: LF | AO5: CRI | AP5: Título Público
B6: LFSN | C6: CRA | F6: =J6+L6+N6+P6+R6+T6 -> 1 | H6: Riza Lotus | I6: 3971003000 | J6: ='Fev26'!J6+'Abr26'!J41 -> 0.218 | K6: 897446678 | L6: ='Fev26'!L6+'Abr26'!L41 -> 0.28966667 | M6: 1.9682938e+09 | N6: ='Fev26'!N6+'Abr26'!N41 -> 0.39766667 | O6: 1.3276387e+09 | P6: ='Fev26'!P6+'Abr26'!P41 -> 0.069333333 | Q6: 21178683 | R6: ='Fev26'!R6+'Abr26'!R41 -> 0 | S6: -4.2357365e+08 | T6: ='Fev26'!T6+'Abr26'!T41 -> 0.025333333 | U6: =+T6*$I6 -> 1.0059874e+08 | Y6: =K6-'Fev26'!K6 -> 897446678 | Z6: =M6-'Fev26'!M6 -> 1.9682938e+09 | AA6: =O6-'Fev26'!O6 -> 1.3276387e+09 | AB6: =Q6-'Fev26'!Q6 -> 21178683 | AC6: =+S6-'Fev26'!S6 -> -4.2357365e+08 | AE6: =J6-'Fev26'!J6 -> 0.038 | AF6: =L6-'Fev26'!L6 -> -0.024666667 | AG6: =N6-'Fev26'!N6 -> -0.013666667 | AH6: =P6-'Fev26'!P6 -> 0.0026666667 | AI6: =R6-'Fev26'!R6 -> 0 | AK6: =I6-'Fev26'!I6 -> -42872000 | AL6: =I6/'Fev26'!I6-1 -> -0.01068095 | AN6: LFSN | AO6: CRA
B7: LFSC | C7: Nota Promissória | F7: =J7+L7+N7+P7+R7+T7 -> 1 | H7: Western Asset Total | I7: 3883790000 | J7: 0.232 | K7: =+J7*$I7 -> 901039280 | L7: 0.326 | M7: =+L7*$I7 -> 1266115540 | N7: 0.306 | O7: =+N7*$I7 -> 1188439740 | P7: 0.136 | Q7: =+P7*$I7 -> 5.2819544e+08 | R7: 0 | S7: =+R7*$I7 -> 0 | T7: 0 | U7: =+T7*$I7 -> 0 | Y7: =K7-'Fev26'!K7 -> 7766669 | Z7: =M7-'Fev26'!M7 -> 17080677 | AA7: =O7-'Fev26'!O7 -> -21925313 | AB7: =Q7-'Fev26'!Q7 -> 13886967 | AC7: =+S7-'Fev26'!S7 -> 0 | AE7: =J7-'Fev26'!J7 -> 0.001 | AF7: =L7-'Fev26'!L7 -> 0.003 | AG7: =N7-'Fev26'!N7 -> -0.007 | AH7: =P7-'Fev26'!P7 -> 0.003 | AI7: =R7-'Fev26'!R7 -> 0 | AK7: =I7-'Fev26'!I7 -> 16809000 | AL7: =I7/'Fev26'!I7-1 -> 0.0043468018 | AN7: LFSC | AO7: Nota Promissória
B8: DPGE | F8: =J8+L8+N8+P8+R8+T8 -> 1 | H8: Daycoval Classic | I8: 2.4435438e+08 | J8: 0.13 | K8: =+J8*$I8 -> 31766070 | L8: 0.45 | M8: =+L8*$I8 -> 1.0995947e+08 | N8: 0.22 | O8: =+N8*$I8 -> 53757964 | P8: 0.08 | Q8: =+P8*$I8 -> 19548351 | R8: 0 | S8: =+R8*$I8 -> 0 | T8: 0.12 | U8: =+T8*$I8 -> 29322526 | Y8: =K8-'Fev26'!K8 -> -2978575.3 | Z8: =M8-'Fev26'!M8 -> 18054282 | AA8: =O8-'Fev26'!O8 -> 3322189.1 | AB8: =Q8-'Fev26'!Q8 -> -625959.44 | AC8: =+S8-'Fev26'!S8 -> 0 | AE8: =J8-'Fev26'!J8 -> -0.025 | AF8: =L8-'Fev26'!L8 -> 0.04 | AG8: =N8-'Fev26'!N8 -> -0.005 | AH8: =P8-'Fev26'!P8 -> -0.01 | AI8: =R8-'Fev26'!R8 -> 0 | AK8: =I8-'Fev26'!I8 -> 20195382 | AL8: =I8/'Fev26'!I8-1 -> 0.090094005 | AN8: DPGE
F9: =J9+L9+N9+P9+R9+T9 -> 1 | H9: Iridium Apollo | I9: 1432338623 | J9: 0.5963 | K9: =+J9*$I9 -> 8.5410352e+08 | L9: 0.1713 | M9: =+L9*$I9 -> 2.4535961e+08 | N9: 0.1707 | O9: =+N9*$I9 -> 2.445002e+08 | P9: 0.0498 | Q9: =+P9*$I9 -> 71330463 | R9: 0 | S9: =+R9*$I9 -> 0 | T9: 0.0119 | U9: =+T9*$I9 -> 17044830 | Y9: =K9-'Fev26'!K9 -> -31693459 | Z9: =M9-'Fev26'!M9 -> -47270.28 | AA9: =O9-'Fev26'!O9 -> -28190715 | AB9: =Q9-'Fev26'!Q9 -> -2672828.6 | AC9: =+S9-'Fev26'!S9 -> 0 | AE9: =J9-'Fev26'!J9 -> 0.0038 | AF9: =L9-'Fev26'!L9 -> 0.00715 | AG9: =N9-'Fev26'!N9 -> -0.0117 | AH9: =P9-'Fev26'!P9 -> 0.0003 | AI9: =R9-'Fev26'!R9 -> 0 | AK9: =I9-'Fev26'!I9 -> -62677377 | AL9: =I9/'Fev26'!I9-1 -> -0.041924218
F10: =J10+L10+N10+P10+R10+T10 -> 1 | H10: Porto Seguro FIRF | I10: 7.5957034e+09 | J10: 0.364 | K10: =+J10*$I10 -> 2.764836e+09 | L10: 0.356 | M10: =+L10*$I10 -> 2.7040704e+09 | N10: 0.225 | O10: =+N10*$I10 -> 1.7090333e+09 | P10: 0.055 | Q10: =+P10*$I10 -> 4.1776369e+08 | R10: 0 | S10: =+R10*$I10 -> 0 | T10: 0 | U10: =+T10*$I10 -> 0 | Y10: =K10-'Fev26'!K10 -> -72116797 | Z10: =M10-'Fev26'!M10 -> -1.922329e+08 | AA10: =O10-'Fev26'!O10 -> -63567669 | AB10: =Q10-'Fev26'!Q10 -> 10223740 | AC10: =+S10-'Fev26'!S10 -> 0 | AE10: =J10-'Fev26'!J10 -> 0.0055 | AF10: =L10-'Fev26'!L10 -> -0.01 | AG10: =N10-'Fev26'!N10 -> 0.001 | AH10: =P10-'Fev26'!P10 -> 0.0035 | AI10: =R10-'Fev26'!R10 -> 0 | AK10: =I10-'Fev26'!I10 -> -3.1769363e+08 | AL10: =I10/'Fev26'!I10-1 -> -0.040146302
F11: =J11+L11+N11+P11+R11+T11 -> 1 | H11: Nu Reserva Imediata | I11: 2.8655764e+09 | J11: 0.62 | K11: =+J11*$I11 -> 1.7766573e+09 | L11: 0.27 | M11: =+L11*$I11 -> 7.7370562e+08 | N11: 0.11 | O11: =+N11*$I11 -> 3.152134e+08 | P11: 0 | Q11: =+P11*$I11 -> 0 | R11: 0 | S11: =+R11*$I11 -> 0 | T11: 0 | U11: =+T11*$I11 -> 0 | Y11: =K11-'Fev26'!K11 -> 66144384 | Z11: =M11-'Fev26'!M11 -> -96046735 | AA11: =O11-'Fev26'!O11 -> -3695796.2 | AB11: =Q11-'Fev26'!Q11 -> 0 | AC11: =+S11-'Fev26'!S11 -> 0 | AE11: =J11-'Fev26'!J11 -> 0.03 | AF11: =L11-'Fev26'!L11 -> -0.03 | AG11: =N11-'Fev26'!N11 -> 0 | AH11: =P11-'Fev26'!P11 -> 0 | AI11: =R11-'Fev26'!R11 -> 0 | AK11: =I11-'Fev26'!I11 -> -33598147 | AL11: =I11/'Fev26'!I11-1 -> -0.011588867
B12: Pegar fora da XP: | F12: =J12+L12+N12+P12+R12+T12 -> 1 | H12: Inter Conservador | I12: 1389750000 | J12: 0.251 | K12: =+J12*$I12 -> 348827250 | L12: =34.3%+13.6% -> 0.479 | M12: =+L12*$I12 -> 665690250 | N12: =22.2%+2.3% -> 0.245 | O12: =+N12*$I12 -> 340488750 | P12: 0.025 | Q12: =+P12*$I12 -> 34743750 | R12: 0 | S12: =+R12*$I12 -> 0 | T12: 0 | U12: =+T12*$I12 -> 0 | Y12: =K12-'Fev26'!K12 -> -4691335 | Z12: =M12-'Fev26'!M12 -> -37739588 | AA12: =O12-'Fev26'!O12 -> -9422502.5 | AB12: =Q12-'Fev26'!Q12 -> -1329575 | AC12: =+S12-'Fev26'!S12 -> 0 | AE12: =J12-'Fev26'!J12 -> 0.006 | AF12: =L12-'Fev26'!L12 -> -0.0085 | AG12: =N12-'Fev26'!N12 -> 0.0025 | AH12: =P12-'Fev26'!P12 -> 0 | AI12: =R12-'Fev26'!R12 -> 0 | AK12: =I12-'Fev26'!I12 -> -53183000 | AL12: =I12/'Fev26'!I12-1 -> -0.036857567
B13: NU Reserva Imediata | F13: =J13+L13+N13+P13+R13+T13 -> 1 | H13: Absolute Atenas | I13: 788100000 | J13: 0.06 | K13: =+J13*$I13 -> 47286000 | L13: 0.59 | M13: =+L13*$I13 -> 464979000 | N13: 0.2 | O13: =+N13*$I13 -> 157620000 | P13: 0.15 | Q13: =+P13*$I13 -> 118215000 | R13: 0 | S13: =+R13*$I13 -> 0 | T13: 0 | U13: =+T13*$I13 -> 0 | Y13: =K13-'Fev26'!K13 -> -1.9340592e+08 | Z13: =M13-'Fev26'!M13 -> 69556560 | AA13: =O13-'Fev26'!O13 -> 2889480 | AB13: =Q13-'Fev26'!Q13 -> 49445880 | AC13: =+S13-'Fev26'!S13 -> 0 | AE13: =J13-'Fev26'!J13 -> -0.22 | AF13: =L13-'Fev26'!L13 -> 0.13 | AG13: =N13-'Fev26'!N13 -> 0.02 | AH13: =P13-'Fev26'!P13 -> 0.07 | AI13: =R13-'Fev26'!R13 -> 0 | AK13: =I13-'Fev26'!I13 -> -71514000 | AL13: =I13/'Fev26'!I13-1 -> -0.083193154
B14: JGP Select | F14: =J14+L14+N14+P14+R14+T14 -> 0.99676971 | H14: TOTAL | I14: =SUM(I3:I13) -> 2.4586069e+10 | J14: =K14/$I$14 -> 0.35067892 | K14: =SUM(K3:K13) -> 8.6218161e+09 | L14: =M14/$I$14 -> 0.35503252 | M14: =SUM(M3:M13) -> 8.7288539e+09 | N14: =O14/$I$14 -> 0.24121581 | O14: =SUM(O3:O13) -> 5.9305486e+09 | P14: =Q14/$I$14 -> 0.060274537 | Q14: =SUM(Q3:Q13) -> 1.4819139e+09 | R14: =S14/$I$14 -> -0.016377975 | S14: =SUM(S3:S13) -> -4.0267003e+08 | T14: =U14/$I$14 -> 0.0059459065 | U14: =SUM(U3:U13) -> 1.4618647e+08 | Y14: =K14-'Fev26'!K14 -> 5.8579149e+08 | Z14: =M14-'Fev26'!M14 -> 1.7340099e+09 | AA14: =O14-'Fev26'!O14 -> 1.1934189e+09 | AB14: =Q14-'Fev26'!Q14 -> 87558992 | AC14: =+S14-'Fev26'!S14 -> -4.2935359e+08 | AE14: =J14-'Fev26'!J14 -> 0.032386931 | AF14: =L14-'Fev26'!L14 -> 0.077979756 | AG14: =N14-'Fev26'!N14 -> 0.053586915 | AH14: =P14-'Fev26'!P14 -> 0.0050467316 | AI14: =R14-'Fev26'!R14 -> -0.017434862 | AK14: =I14-'Fev26'!I14 -> -6.6126651e+08 | AL14: =I14/'Fev26'!I14-1 -> -0.026191536
B15: Absolute Olimpia
H16: Fundo D+30 | I16: PL | J16: Caixa | L16: Bancários | N16: Corporativo | P16: FIDC | R16: FII | T16: Outros | Y16: Δ Caixa | Z16: Δ Bancários | AA16: Δ Corporativo | AB16: Δ FIDC | AC16: Δ FII | AE16: Δ Caixa | AF16: Δ Bancários | AG16: Δ Corporativo | AH16: Δ FIDC | AI16: Δ FII
F17: =J17+L17+N17+P17+R17+T17 -> 1 | H17: Geraes 30 | I17: 3.2206528e+08 | J17: 0.3289 | K17: =+J17*$I17 -> 1.0592727e+08 | L17: =10.97%+6.49%+4.68%+4.31% -> 0.2645 | M17: =+L17*$I17 -> 85186267 | N17: =25.72%+0.84% -> 0.2656 | O17: =+N17*$I17 -> 85540538 | P17: 0.0762 | Q17: =+P17*$I17 -> 24541374 | R17: 0 | S17: =+R17*$I17 -> 0 | T17: 0.0648 | U17: =+T17*$I17 -> 20869830 | Y17: =K17-'Fev26'!K17 -> -55900363 | Z17: =M17-'Fev26'!M17 -> 1869069 | AA17: =O17-'Fev26'!O17 -> -5330141.4 | AB17: =Q17-'Fev26'!Q17 -> 354971.75 | AC17: =+S17-'Fev26'!S17 -> 0 | AE17: =J17-'Fev26'!J17 -> -0.0953 | AF17: =L17-'Fev26'!L17 -> 0.0461 | AG17: =N17-'Fev26'!N17 -> 0.0274 | AH17: =P17-'Fev26'!P17 -> 0.0128 | AI17: =R17-'Fev26'!R17 -> 0 | AK17: =I17-'Fev26'!I17 -> -59423720 | AL17: =I17/'Fev26'!I17-1 -> -0.15576785
F18: =J18+L18+N18+P18+R18+T18 -> 1 | H18: Daycoval Classic 30 | I18: 8.6121529e+08 | J18: 0.08 | K18: =+J18*$I18 -> 68897223 | L18: 0.25 | M18: =+L18*$I18 -> 2.1530382e+08 | N18: 0.38 | O18: =+N18*$I18 -> 3.2726181e+08 | P18: 0.17 | Q18: =+P18*$I18 -> 1.464066e+08 | R18: 0 | S18: =+R18*$I18 -> 0 | T18: 0.12 | U18: =+T18*$I18 -> 1.0334583e+08 | Y18: =K18-'Fev26'!K18 -> 10141043 | Z18: =M18-'Fev26'!M18 -> 5460321.9 | AA18: =O18-'Fev26'!O18 -> 4102819.2 | AB18: =Q18-'Fev26'!Q18 -> -483851.13 | AC18: =+S18-'Fev26'!S18 -> 0 | AE18: =J18-'Fev26'!J18 -> 0.01 | AF18: =L18-'Fev26'!L18 -> 0 | AG18: =N18-'Fev26'!N18 -> -0.005 | AH18: =P18-'Fev26'!P18 -> -0.005 | AI18: =R18-'Fev26'!R18 -> 0 | AK18: =I18-'Fev26'!I18 -> 21841287 | AL18: =I18/'Fev26'!I18-1 -> 0.026020924
F19: =J19+L19+N19+P19+R19+T19 -> 1 | H19: Riza Lotus Plus | I19: 526410678 | J19: 0.155 | K19: =+J19*$I19 -> 81593655 | L19: 0.187 | M19: =+L19*$I19 -> 98438797 | N19: 0.537 | O19: =+N19*$I19 -> 2.8268253e+08 | P19: 0.091 | Q19: =+P19*$I19 -> 47903372 | R19: 0 | S19: =+R19*$I19 -> 0 | T19: 0.03 | U19: =+T19*$I19 -> 15792320 | Y19: =K19-'Fev26'!K19 -> 18525791 | Z19: =M19-'Fev26'!M19 -> -27974763 | AA19: =O19-'Fev26'!O19 -> -14875538 | AB19: =Q19-'Fev26'!Q19 -> -161564.3 | AC19: =+S19-'Fev26'!S19 -> 0 | AE19: =J19-'Fev26'!J19 -> 0.0415 | AF19: =L19-'Fev26'!L19 -> -0.0405 | AG19: =N19-'Fev26'!N19 -> 0.0015 | AH19: =P19-'Fev26'!P19 -> 0.0045 | AI19: =R19-'Fev26'!R19 -> 0 | AK19: =I19-'Fev26'!I19 -> -29253322 | AL19: =I19/'Fev26'!I19-1 -> -0.052645703
C20: LEGENDA: | F20: =J20+L20+N20+P20+R20+T20 -> 1 | H20: ARX Vinson Advisory | I20: 1291980680 | J20: 0.21 | K20: =+J20*$I20 -> 2.7131594e+08 | L20: 0.32 | M20: =+L20*$I20 -> 4.1343382e+08 | N20: 0.29 | O20: =+N20*$I20 -> 3.746744e+08 | P20: 0.18 | Q20: =+P20*$I20 -> 2.3255652e+08 | R20: 0 | S20: =+R20*$I20 -> 0 | T20: 0 | U20: =+T20*$I20 -> 0 | Y20: =K20-'Fev26'!K20 -> -372397.2 | Z20: =M20-'Fev26'!M20 -> -567462.4 | AA20: =O20-'Fev26'!O20 -> -514262.8 | AB20: =Q20-'Fev26'!Q20 -> -319197.6 | AC20: =+S20-'Fev26'!S20 -> 0 | AE20: =J20-'Fev26'!J20 -> 0 | AF20: =L20-'Fev26'!L20 -> 0 | AG20: =N20-'Fev26'!N20 -> 0 | AH20: =P20-'Fev26'!P20 -> 0 | AI20: =R20-'Fev26'!R20 -> 0 | AK20: =I20-'Fev26'!I20 -> -1773320 | AL20: =I20/'Fev26'!I20-1 -> -0.0013706779
B21: Bancário: | C21: Corporativo | D21: Caixa | F21: =J21+L21+N21+P21+R21+T21 -> 1.01 | H21: Sparta Max Advisory | I21: 149250000 | J21: 0.2 | K21: =+J21*$I21 -> 29850000 | L21: 0.17 | M21: =+L21*$I21 -> 25372500 | N21: 0.52 | O21: =+N21*$I21 -> 77610000 | P21: 0.12 | Q21: =+P21*$I21 -> 17910000 | R21: 0 | S21: =+R21*$I21 -> 0 | T21: 0 | U21: =+T21*$I21 -> 0 | Y21: =K21-'Fev26'!K21 -> -3750160 | Z21: =M21-'Fev26'!M21 -> -591260 | AA21: =O21-'Fev26'!O21 -> 2009640 | AB21: =Q21-'Fev26'!Q21 -> -417360 | AC21: =+S21-'Fev26'!S21 -> 0 | AE21: =J21-'Fev26'!J21 -> -0.02 | AF21: =L21-'Fev26'!L21 -> 0 | AG21: =N21-'Fev26'!N21 -> 0.025 | AH21: =P21-'Fev26'!P21 -> 0 | AI21: =R21-'Fev26'!R21 -> 0 | AK21: =I21-'Fev26'!I21 -> -3478000 | AL21: =I21/'Fev26'!I21-1 -> -0.022772511
B22: CDB | C22: Debênture | D22: Compromissada | F22: =J22+L22+N22+P22+R22+T22 -> 1 | H22: Polo Crédito Corporativo | I22: 1254200000 | J22: 0.16 | K22: =+J22*$I22 -> 200672000 | L22: 0.32 | M22: =+L22*$I22 -> 401344000 | N22: 0.48 | O22: =+N22*$I22 -> 602016000 | P22: 0.04 | Q22: =+P22*$I22 -> 50168000 | R22: 0 | S22: =+R22*$I22 -> 0 | T22: 0 | U22: =+T22*$I22 -> 0 | Y22: =K22-'Fev26'!K22 -> -22076575 | Z22: =M22-'Fev26'!M22 -> 19489300 | AA22: =O22-'Fev26'!O22 -> -21680010 | AB22: =Q22-'Fev26'!Q22 -> 5618285 | AC22: =+S22-'Fev26'!S22 -> 0 | AE22: =J22-'Fev26'!J22 -> -0.015 | AF22: =L22-'Fev26'!L22 -> 0.02 | AG22: =N22-'Fev26'!N22 -> -0.01 | AH22: =P22-'Fev26'!P22 -> 0.005 | AI22: =R22-'Fev26'!R22 -> 0 | AK22: =I22-'Fev26'!I22 -> -18649000 | AL22: =I22/'Fev26'!I22-1 -> -0.014651384
B23: LF | C23: CRI | D23: Título Público | F23: =J23+L23+N23+P23+R23+T23 -> 1 | H23: Iridium Titan Advisory | I23: 205827081 | J23: 0.4924 | K23: =+J23*$I23 -> 1.0134925e+08 | L23: 0.1299 | M23: =+L23*$I23 -> 26736938 | N23: 0.2619 | O23: =+N23*$I23 -> 53906113 | P23: 0.1031 | Q23: =+P23*$I23 -> 21220772 | R23: 0 | S23: =+R23*$I23 -> 0 | T23: 0.0127 | U23: =+T23*$I23 -> 2614003.9 | Y23: =K23-'Fev26'!K23 -> -3120916.9 | Z23: =M23-'Fev26'!M23 -> 989391.27 | AA23: =O23-'Fev26'!O23 -> -2301841.7 | AB23: =Q23-'Fev26'!Q23 -> 301546.5 | AC23: =+S23-'Fev26'!S23 -> 0 | AE23: =J23-'Fev26'!J23 -> -0.00525 | AF23: =L23-'Fev26'!L23 -> 0.00725 | AG23: =N23-'Fev26'!N23 -> -0.00585 | AH23: =P23-'Fev26'!P23 -> 0.00345 | AI23: =R23-'Fev26'!R23 -> 0 | AK23: =I23-'Fev26'!I23 -> -4099919 | AL23: =I23/'Fev26'!I23-1 -> -0.019530213
B24: LFSN | C24: CRA | F24: =J24+L24+N24+P24+R24+T24 -> 1 | H24: Porto Seguro Ipê | I24: 5.5013124e+08 | J24: 0.13 | K24: =+J24*$I24 -> 71517061 | L24: 0.403 | M24: =+L24*$I24 -> 2.2170289e+08 | N24: 0.354 | O24: =+N24*$I24 -> 1.9474646e+08 | P24: 0.113 | Q24: =+P24*$I24 -> 62164830 | R24: 0 | S24: =+R24*$I24 -> 0 | T24: 0 | U24: =+T24*$I24 -> 0 | Y24: =K24-'Fev26'!K24 -> 10512884 | Z24: =M24-'Fev26'!M24 -> -9892154.7 | AA24: =O24-'Fev26'!O24 -> -5380367.3 | AB24: =Q24-'Fev26'!Q24 -> 2816874.7 | AC24: =+S24-'Fev26'!S24 -> 0 | AE24: =J24-'Fev26'!J24 -> 0.0195 | AF24: =L24-'Fev26'!L24 -> -0.0165 | AG24: =N24-'Fev26'!N24 -> -0.0085 | AH24: =P24-'Fev26'!P24 -> 0.0055 | AI24: =R24-'Fev26'!R24 -> 0 | AK24: =I24-'Fev26'!I24 -> -1942763.6 | AL24: =I24/'Fev26'!I24-1 -> -0.0035190276
B25: LFSC | C25: Nota Promissória | F25: =J25+L25+N25+P25+R25+T25 -> 1 | H25: Sparta Top Advisory | I25: 610000000 | J25: 0.19 | K25: =+J25*$I25 -> 115900000 | L25: 0.25 | M25: =+L25*$I25 -> 152500000 | N25: 0.47 | O25: =+N25*$I25 -> 286700000 | P25: 0.09 | Q25: =+P25*$I25 -> 54900000 | R25: 0 | S25: =+R25*$I25 -> 0 | T25: 0 | U25: =+T25*$I25 -> 0 | Y25: =K25-'Fev26'!K25 -> -6109600 | Z25: =M25-'Fev26'!M25 -> -3062240 | AA25: =O25-'Fev26'!O25 -> 9128160 | AB25: =Q25-'Fev26'!Q25 -> -4320 | AC25: =+S25-'Fev26'!S25 -> 0 | AE25: =J25-'Fev26'!J25 -> -0.01 | AF25: =L25-'Fev26'!L25 -> -0.005 | AG25: =N25-'Fev26'!N25 -> 0.015 | AH25: =P25-'Fev26'!P25 -> 0 | AI25: =R25-'Fev26'!R25 -> 0 | AK25: =I25-'Fev26'!I25 -> -48000 | AL25: =I25/'Fev26'!I25-1 -> -7.8682333e-05
B26: DPGE | F26: =J26+L26+N26+P26+R26+T26 -> 1 | H26: Absolute Creta | I26: 1919115000 | J26: 0.21 | K26: =+J26*$I26 -> 403014150 | L26: 0.24 | M26: =+L26*$I26 -> 460587600 | N26: 0.44 | O26: =+N26*$I26 -> 844410600 | P26: 0.11 | Q26: =+P26*$I26 -> 211102650 | R26: 0 | S26: =+R26*$I26 -> 0 | T26: 0 | U26: =+T26*$I26 -> 0 | Y26: =K26-'Fev26'!K26 -> -171857200 | Z26: =M26-'Fev26'!M26 -> 34389875 | AA26: =O26-'Fev26'!O26 -> -7984850 | AB26: =Q26-'Fev26'!Q26 -> 82252175 | AC26: =+S26-'Fev26'!S26 -> 0 | AE26: =J26-'Fev26'!J26 -> -0.08 | AF26: =L26-'Fev26'!L26 -> 0.025 | AG26: =N26-'Fev26'!N26 -> 0.01 | AH26: =P26-'Fev26'!P26 -> 0.045 | AI26: =R26-'Fev26'!R26 -> 0 | AK26: =I26-'Fev26'!I26 -> -63200000 | AL26: =I26/'Fev26'!I26-1 -> -0.031881916
F27: =J27+L27+N27+P27+R27+T27 -> 1.0001941 | H27: TOTAL | I27: =SUM(I17:I26) -> 7.6901952e+09 | J27: =K27/$I$27 -> 0.18855653 | K27: =SUM(K17:K26) -> 1.4500366e+09 | L27: =M27/$I$27 -> 0.27315387 | M27: =SUM(M17:M26) -> 2.1006066e+09 | N27: =O27/$I$27 -> 0.40695306 | O27: =SUM(O17:O26) -> 3.1295484e+09 | P27: =Q27/$I$27 -> 0.11298466 | Q27: =SUM(Q17:Q26) -> 8.6887412e+08 | R27: =S27/$I$27 -> 0 | S27: =SUM(S17:S26) -> 0 | T27: =U27/$I$27 -> 0.018545952 | U27: =SUM(U17:U26) -> 1.4262199e+08 | Y27: =K27-'Fev26'!K27 -> -2.2400749e+08 | Z27: =M27-'Fev26'!M27 -> 20110077 | AA27: =O27-'Fev26'!O27 -> -42826392 | AB27: =Q27-'Fev26'!Q27 -> 89957560 | AC27: =+S27-'Fev26'!S27 -> 0 | AE27: =J27-'Fev26'!J27 -> -0.024691455 | AF27: =L27-'Fev26'!L27 -> 0.0081299619 | AG27: =N27-'Fev26'!N27 -> 0.0028403 | AH27: =P27-'Fev26'!P27 -> 0.01376243 | AI27: =R27-'Fev26'!R27 -> 0 | AK27: =I27-'Fev26'!I27 -> -1.6002676e+08 | AL27: =I27/'Fev26'!I27-1 -> -0.020384998
H29: Fundo D+60 | I29: PL | J29: Caixa | L29: Bancários | N29: Corporativo | P29: FIDC | R29: Bonds | T29: Outros | Y29: Δ Caixa | Z29: Δ Bancários | AA29: Δ Corporativo | AB29: Δ FIDC | AC29: Δ Bonds | AE29: Δ Caixa | AF29: Δ Bancários | AG29: Δ Corporativo | AH29: Δ FIDC | AI29: Δ Bonds
F30: =J30+L30+N30+P30+R30+T30 -> 1 | H30: Horizonte | I30: 2.2720126e+08 | J30: =16.52%+1.41% -> 0.1793 | K30: =+J30*$I30 -> 40737187 | L30: =8.61%+7.73%+3.06% -> 0.194 | M30: =+L30*$I30 -> 44077045 | N30: =36.14%+1.88%+1.15% -> 0.3917 | O30: =+N30*$I30 -> 88994735 | P30: 0.1563 | Q30: =+P30*$I30 -> 35511558 | R30: 0.0541 | S30: =+R30*$I30 -> 12291588 | T30: 0.0246 | U30: =+T30*$I30 -> 5589151.1 | Y30: =K30-'Fev26'!K30 -> 9915470.9 | Z30: =M30-'Fev26'!M30 -> -3062049.4 | AA30: =O30-'Fev26'!O30 -> -6637498.2 | AB30: =Q30-'Fev26'!Q30 -> -795184.23 | AC30: =+S30-'Fev26'!S30 -> -1432451.8 | AE30: =J30-'Fev26'!J30 -> 0.045 | AF30: =L30-'Fev26'!L30 -> -0.0114 | AG30: =N30-'Fev26'!N30 -> -0.025 | AH30: =P30-'Fev26'!P30 -> -0.0019 | AI30: =R30-'Fev26'!R30 -> -0.0057 | AK30: =I30-'Fev26'!I30 -> -2297735.9 | AL30: =I30/'Fev26'!I30-1 -> -0.010011965
F31: =J31+L31+N31+P31+R31+T31 -> 0 | H31: BTG PACTUAL CRED PLUS | K31: =+J31*$I31 -> 0 | M31: =+L31*$I31 -> 0 | O31: =+N31*$I31 -> 0 | Q31: =+P31*$I31 -> 0 | S31: =+R31*$I31 -> 0 | U31: =+T31*$I31 -> 0 | Y31: =K31-'Fev26'!K31 -> 0 | Z31: =M31-'Fev26'!M31 -> 0 | AA31: =O31-'Fev26'!O31 -> 0 | AB31: =Q31-'Fev26'!Q31 -> 0 | AC31: =+S31-'Fev26'!S31 -> 0 | AE31: =J31-'Fev26'!J31 -> 0 | AF31: =L31-'Fev26'!L31 -> 0 | AG31: =N31-'Fev26'!N31 -> 0 | AH31: =P31-'Fev26'!P31 -> 0 | AI31: =R31-'Fev26'!R31 -> 0 | AK31: =I31-'Fev26'!I31 -> 0 | AL31: =I31/'Fev26'!I31-1 -> #DIV/0!
F32: =J32+L32+N32+P32+R32+T32 -> 1 | H32: JGP Select | I32: 323176836 | J32: 0.07 | K32: =+J32*$I32 -> 22622379 | L32: 0.11 | M32: =+L32*$I32 -> 35549452 | N32: 0.5 | O32: =+N32*$I32 -> 161588418 | P32: 0.08 | Q32: =+P32*$I32 -> 25854147 | R32: 0.18 | S32: =+R32*$I32 -> 58171830 | T32: 0.06 | U32: =+T32*$I32 -> 19390610 | Y32: =K32-'Fev26'!K32 -> -1162296.5 | Z32: =M32-'Fev26'!M32 -> -920383.04 | AA32: =O32-'Fev26'!O32 -> 3023918 | AB32: =Q32-'Fev26'!Q32 -> -1101818.1 | AC32: =+S32-'Fev26'!S32 -> 1088610.5 | AE32: =J32-'Fev26'!J32 -> -0.005 | AF32: =L32-'Fev26'!L32 -> -0.005 | AG32: =N32-'Fev26'!N32 -> 0 | AH32: =P32-'Fev26'!P32 -> -0.005 | AI32: =R32-'Fev26'!R32 -> 0 | AK32: =I32-'Fev26'!I32 -> 6047836 | AL32: =I32/'Fev26'!I32-1 -> 0.019070586
F33: =J33+L33+N33+P33+R33+T33 -> 1 | H33: ARX Everest Advisory | I33: 451832856 | J33: 0.21 | K33: =+J33*$I33 -> 94884900 | L33: 0.21 | M33: =+L33*$I33 -> 94884900 | N33: 0.4 | O33: =+N33*$I33 -> 1.8073314e+08 | P33: 0.18 | Q33: =+P33*$I33 -> 81329914 | R33: 0 | S33: =+R33*$I33 -> 0 | T33: 0 | U33: =+T33*$I33 -> 0 | Y33: =K33-'Fev26'!K33 -> 8208039.8 | Z33: =M33-'Fev26'!M33 -> 3646099.8 | AA33: =O33-'Fev26'!O33 -> -13149308 | AB33: =Q33-'Fev26'!Q33 -> -785005.92 | AC33: =+S33-'Fev26'!S33 -> 0 | AE33: =J33-'Fev26'!J33 -> 0.02 | AF33: =L33-'Fev26'!L33 -> 0.01 | AG33: =N33-'Fev26'!N33 -> -0.025 | AH33: =P33-'Fev26'!P33 -> 0 | AI33: =R33-'Fev26'!R33 -> 0 | AK33: =I33-'Fev26'!I33 -> -4361144 | AL33: =I33/'Fev26'!I33-1 -> -0.0095598452
F34: =J34+L34+N34+P34+R34+T34 -> 1 | H34: Polo Total | I34: 78100000 | J34: 0.04 | K34: =+J34*$I34 -> 3124000 | L34: 0.26 | M34: =+L34*$I34 -> 20306000 | N34: 0.48 | O34: =+N34*$I34 -> 37488000 | P34: 0.04 | Q34: =+P34*$I34 -> 3124000 | R34: 0.18 | S34: =+R34*$I34 -> 14058000 | T34: 0 | U34: =+T34*$I34 -> 0 | Y34: =K34-'Fev26'!K34 -> 63640 | Z34: =M34-'Fev26'!M34 -> 796205 | AA34: =O34-'Fev26'!O34 -> -1531590 | AB34: =Q34-'Fev26'!Q34 -> 828730 | AC34: =+S34-'Fev26'!S34 -> 1434015 | AE34: =J34-'Fev26'!J34 -> 0 | AF34: =L34-'Fev26'!L34 -> 0.005 | AG34: =N34-'Fev26'!N34 -> -0.03 | AH34: =P34-'Fev26'!P34 -> 0.01 | AI34: =R34-'Fev26'!R34 -> 0.015 | AK34: =I34-'Fev26'!I34 -> 1591000 | AL34: =I34/'Fev26'!I34-1 -> 0.020794939
F35: =J35+L35+N35+P35+R35+T35 -> 1 | H35: Absolute Olimpia | I35: 305268000 | J35: 0.056666667 | K35: 17298520 | L35: 0.01 | M35: 3052680 | N35: 0.42666667 | O35: 1.3024768e+08 | P35: 0.42 | Q35: 1.2821256e+08 | R35: 0.086666667 | S35: 26456560 | T35: 0 | U35: =+T35*$I35 -> 0 | Y35: =K35-'Fev26'!K35 -> -8327173.3 | Z35: =M35-'Fev26'!M35 -> -2438540 | AA35: =O35-'Fev26'!O35 -> 288806.67 | AB35: =Q35-'Fev26'!Q35 -> 48589870 | AC35: =+S35-'Fev26'!S35 -> -7405963.3 | AE35: =J35-'Fev26'!J35 -> -0.036666667 | AF35: =L35-'Fev26'!L35 -> -0.01 | AG35: =N35-'Fev26'!N35 -> -0.046666667 | AH35: =P35-'Fev26'!P35 -> 0.13 | AI35: =R35-'Fev26'!R35 -> -0.036666667 | AK35: =I35-'Fev26'!I35 -> 30707000 | AL35: =I35/'Fev26'!I35-1 -> 0.11184036
F36: =J36+L36+N36+P36+R36+T36 -> 1 | H36: TOTAL | I36: =SUM(I30:I35) -> 1.385579e+09 | J36: =+K36/$I$36 -> 0.12894753 | K36: =SUM(K30:K35) -> 1.7866698e+08 | L36: =+M36/$I$36 -> 0.14280679 | M36: =SUM(M30:M35) -> 1.9787008e+08 | N36: =+O36/$I$36 -> 0.43234777 | O36: =SUM(O30:O35) -> 5.9905198e+08 | P36: =+Q36/$I$36 -> 0.1977745 | Q36: =SUM(Q30:Q35) -> 2.7403218e+08 | R36: =+S36/$I$36 -> 0.080095023 | S36: =SUM(S30:S35) -> 1.1097798e+08 | T36: =+U36/$I$36 -> 0.018028392 | U36: =SUM(U30:U35) -> 24979761 | Y36: =K36-'Fev26'!K36 -> 8697680.9 | Z36: =M36-'Fev26'!M36 -> -1978667.7 | AA36: =O36-'Fev26'!O36 -> -18005671 | AB36: =Q36-'Fev26'!Q36 -> 46736592 | AC36: =+S36-'Fev26'!S36 -> -6315789.7 | AE36: =J36-'Fev26'!J36 -> 0.0034062733 | AF36: =L36-'Fev26'!L36 -> -0.0048037657 | AG36: =N36-'Fev26'!N36 -> -0.02341801 | AH36: =P36-'Fev26'!P36 -> 0.029891395 | AI36: =R36-'Fev26'!R36 -> -0.0065394855 | AK36: =I36-'Fev26'!I36 -> 31686956 | AL36: =I36/'Fev26'!I36-1 -> 0.023404345

Sheet Fev26
C2: LEGENDA: | H2: Fundo D+1 | I2: PL | J2: Caixa | L2: Bancários | N2: Corporativo | P2: FIDC | R2: FII | T2: Outros | W2: Obs: | Y2: Δ Caixa | Z2: Δ Bancários | AA2: Δ Corporativo | AB2: Δ FIDC | AC2: Δ FII | AE2: Δ Caixa | AF2: Δ Bancários | AG2: Δ Corporativo | AH2: Δ FIDC | AI2: Δ FII | AK2: Var. PL | AL2: % | AO2: LEGENDA:
B3: Bancário | C3: Corporativo | D3: Caixa | F3: =J3+L3+N3+P3+R3+T3 -> 1 | H3: Geraes | I3: 581072000 | J3: 0.6224 | K3: =+J3*$I3 -> 3.6165921e+08 | L3: 0.1818 | M3: =+L3*$I3 -> 1.0563889e+08 | N3: 0.154 | O3: =+N3*$I3 -> 89485088 | P3: 0.0411 | Q3: =+P3*$I3 -> 23882059 | R3: 0 | S3: =+R3*$I3 -> 0 | T3: 0.0007 | U3: =+T3*$I3 -> 406750.4 | Y3: =K3-'Jan26'!K3 -> 1602288.1 | Z3: =M3-'Jan26'!M3 -> -22628670 | AA3: =O3-'Jan26'!O3 -> -16088502 | AB3: =Q3-'Jan26'!Q3 -> -4283333.1 | AC3: =+S3-'Jan26'!S3 -> 0 | AE3: =J3-'Jan26'!J3 -> 0.0433 | AF3: =L3-'Jan26'!L3 -> -0.0245 | AG3: =N3-'Jan26'!N3 -> -0.0158 | AH3: =P3-'Jan26'!P3 -> -0.0042 | AI3: =R3-'Jan26'!R3 -> 0 | AK3: =I3-'Nov25'!I3 -> -44978509 | AL3: =I3/'Nov25'!I3-1 -> -0.071844856 | AN3: Bancário: | AO3: Corporativo | AP3: Caixa
B4: CDB | C4: Debênture | D4: Compromissada | F4: =J4+L4+N4+P4+R4+T4 -> 1 | H4: ARX Denali | I4: 1728751000 | J4: 0.35666667 | K4: 6.1658786e+08 | L4: 0.25333333 | M4: 4.3795025e+08 | N4: 0.25333333 | O4: 4.3795025e+08 | P4: 0.13666667 | Q4: 2.3626264e+08 | R4: 0 | S4: 0 | T4: 0 | U4: =+T4*$I4 -> 0 | Y4: =K4-'Jan26'!K4 -> -11851564 | Z4: =M4-'Jan26'!M4 -> -15922661 | AA4: =O4-'Jan26'!O4 -> 1533989.1 | AB4: =Q4-'Jan26'!Q4 -> 9326179.3 | AC4: =+S4-'Jan26'!S4 -> 0 | AE4: =J4-'Jan26'!J4 -> -0.0033333333 | AF4: =L4-'Jan26'!L4 -> -0.0066666667 | AG4: =N4-'Jan26'!N4 -> 0.0033333333 | AH4: =P4-'Jan26'!P4 -> 0.0066666667 | AI4: =R4-'Jan26'!R4 -> 0 | AK4: =I4-'Nov25'!I4 -> -25442247 | AL4: =I4/'Nov25'!I4-1 -> -0.014503674 | AN4: CDB | AO4: Debênture | AP4: Compromissada
B5: LF | C5: CRI | D5: Título Público | F5: =J5+L5+N5+P5+R5+T5 -> 1 | H5: Capitania Top | I5: 222363000 | J5: =AVERAGE('Mar26'!J5,'Jan26'!J5) -> 0.46 | K5: =+J5*$I5 -> 102286980 | L5: =AVERAGE('Mar26'!L5,'Jan26'!L5) -> 0 | M5: =+L5*$I5 -> 0 | N5: =AVERAGE('Mar26'!N5,'Jan26'!N5) -> 0.36 | O5: =+N5*$I5 -> 80050680 | P5: =AVERAGE('Mar26'!P5,'Jan26'!P5) -> 0.06 | Q5: =+P5*$I5 -> 13341780 | R5: =AVERAGE('Mar26'!R5,'Jan26'!R5) -> 0.12 | S5: =+R5*$I5 -> 26683560 | T5: =AVERAGE('Mar26'!T5,'Jan26'!T5) -> 0 | U5: =+T5*$I5 -> 0 | Y5: =K5-'Jan26'!K5 -> 12897667 | Z5: =M5-'Jan26'!M5 -> 0 | AA5: =O5-'Jan26'!O5 -> -7046599.2 | AB5: =Q5-'Jan26'!Q5 -> -7286523 | AC5: =+S5-'Jan26'!S5 -> -5404911.3 | AE5: =J5-'Jan26'!J5 -> 0.07 | AF5: =L5-'Jan26'!L5 -> 0 | AG5: =N5-'Jan26'!N5 -> -0.02 | AH5: =P5-'Jan26'!P5 -> -0.03 | AI5: =R5-'Jan26'!R5 -> -0.02 | AK5: =I5-'Nov25'!I5 -> -25289254 | AL5: =I5/'Nov25'!I5-1 -> -0.10211599 | AN5: LF | AO5: CRI | AP5: Título Público
B6: LFSN | C6: CRA | F6: =J6+L6+N6+P6+R6+T6 -> 1 | H6: Riza Lotus | I6: 4013875000 | J6: ='Jan26'!J6+'Abr26'!J41 -> 0.18 | L6: ='Jan26'!L6+'Abr26'!L41 -> 0.31433333 | N6: ='Jan26'!N6+'Abr26'!N41 -> 0.41133333 | P6: ='Jan26'!P6+'Abr26'!P41 -> 0.066666667 | R6: ='Jan26'!R6+'Abr26'!R41 -> 0 | T6: ='Jan26'!T6+'Abr26'!T41 -> 0.027666667 | U6: =+T6*$I6 -> 1.1105054e+08 | Y6: =K6-'Jan26'!K6 -> -5.702609e+08 | Z6: =M6-'Jan26'!M6 -> -1.3613975e+09 | AA6: =O6-'Jan26'!O6 -> -1706766765 | AB6: =Q6-'Jan26'!Q6 -> -2.57019e+08 | AC6: =+S6-'Jan26'!S6 -> 0 | AE6: =J6-'Jan26'!J6 -> 0.038 | AF6: =L6-'Jan26'!L6 -> -0.024666667 | AG6: =N6-'Jan26'!N6 -> -0.013666667 | AH6: =P6-'Jan26'!P6 -> 0.0026666667 | AI6: =R6-'Jan26'!R6 -> 0 | AK6: =I6-'Nov25'!I6 -> -135299710 | AL6: =I6/'Nov25'!I6-1 -> -0.032608825 | AN6: LFSN | AO6: CRA
B7: LFSC | C7: Nota Promissória | F7: =J7+L7+N7+P7+R7+T7 -> 1 | H7: Western Asset Total | I7: 3866981000 | J7: =AVERAGE('Mar26'!J7,'Jan26'!J7) -> 0.231 | K7: =+J7*$I7 -> 893272611 | L7: =AVERAGE('Mar26'!L7,'Jan26'!L7) -> 0.323 | M7: =+L7*$I7 -> 1249034863 | N7: =AVERAGE('Mar26'!N7,'Jan26'!N7) -> 0.313 | O7: =+N7*$I7 -> 1210365053 | P7: =AVERAGE('Mar26'!P7,'Jan26'!P7) -> 0.133 | Q7: =+P7*$I7 -> 514308473 | R7: =AVERAGE('Mar26'!R7,'Jan26'!R7) -> 0 | S7: =+R7*$I7 -> 0 | T7: =AVERAGE('Mar26'!T7,'Jan26'!T7) -> 0 | U7: =+T7*$I7 -> 0 | Y7: =K7-'Jan26'!K7 -> 60999211 | Z7: =M7-'Jan26'!M7 -> 91089263 | AA7: =O7-'Jan26'!O7 -> 52419453 | AB7: =Q7-'Jan26'!Q7 -> 43893073 | AC7: =+S7-'Jan26'!S7 -> 0 | AE7: =J7-'Jan26'!J7 -> 0.001 | AF7: =L7-'Jan26'!L7 -> 0.003 | AG7: =N7-'Jan26'!N7 -> -0.007 | AH7: =P7-'Jan26'!P7 -> 0.003 | AI7: =R7-'Jan26'!R7 -> 0 | AK7: =I7-'Nov25'!I7 -> 558521000 | AL7: =I7/'Nov25'!I7-1 -> 0.16881601 | AN7: LFSC | AO7: Nota Promissória
B8: DPGE | F8: =J8+L8+N8+P8+R8+T8 -> 1 | H8: Daycoval Classic | I8: 224159000 | J8: =AVERAGE('Mar26'!J8,'Jan26'!J8) -> 0.155 | K8: =+J8*$I8 -> 34744645 | L8: =AVERAGE('Mar26'!L8,'Jan26'!L8) -> 0.41 | M8: =+L8*$I8 -> 91905190 | N8: =AVERAGE('Mar26'!N8,'Jan26'!N8) -> 0.225 | O8: =+N8*$I8 -> 50435775 | P8: =AVERAGE('Mar26'!P8,'Jan26'!P8) -> 0.09 | Q8: =+P8*$I8 -> 20174310 | R8: =AVERAGE('Mar26'!R8,'Jan26'!R8) -> 0 | S8: =+R8*$I8 -> 0 | T8: =AVERAGE('Mar26'!T8,'Jan26'!T8) -> 0.12 | U8: =+T8*$I8 -> 26899080 | Y8: =K8-'Jan26'!K8 -> -3614975 | Z8: =M8-'Jan26'!M8 -> 13054860 | AA8: =O8-'Jan26'!O8 -> 1420705 | AB8: =Q8-'Jan26'!Q8 -> -1136590 | AC8: =+S8-'Jan26'!S8 -> 0 | AE8: =J8-'Jan26'!J8 -> -0.025 | AF8: =L8-'Jan26'!L8 -> 0.04 | AG8: =N8-'Jan26'!N8 -> -0.005 | AH8: =P8-'Jan26'!P8 -> -0.01 | AI8: =R8-'Jan26'!R8 -> 0 | AK8: =I8-'Nov25'!I8 -> 30007090 | AL8: =I8/'Nov25'!I8-1 -> 0.1545547 | AN8: DPGE
F9: =J9+L9+N9+P9+R9+T9 -> 1 | H9: Iridium Apollo | I9: 1495016000 | J9: =AVERAGE('Mar26'!J9,'Jan26'!J9) -> 0.5925 | K9: =+J9*$I9 -> 885796980 | L9: =AVERAGE('Mar26'!L9,'Jan26'!L9) -> 0.16415 | M9: =+L9*$I9 -> 2.4540688e+08 | N9: =AVERAGE('Mar26'!N9,'Jan26'!N9) -> 0.1824 | O9: =+N9*$I9 -> 2.7269092e+08 | P9: =AVERAGE('Mar26'!P9,'Jan26'!P9) -> 0.0495 | Q9: =+P9*$I9 -> 74003292 | R9: =AVERAGE('Mar26'!R9,'Jan26'!R9) -> 0 | S9: =+R9*$I9 -> 0 | T9: =AVERAGE('Mar26'!T9,'Jan26'!T9) -> 0.01145 | U9: =+T9*$I9 -> 17117933 | Y9: =K9-'Jan26'!K9 -> -13810431 | Z9: =M9-'Jan26'!M9 -> 5491191.7 | AA9: =O9-'Jan26'!O9 -> -23918218 | AB9: =Q9-'Jan26'!Q9 -> -1180476.7 | AC9: =+S9-'Jan26'!S9 -> 0 | AE9: =J9-'Jan26'!J9 -> 0.0038 | AF9: =L9-'Jan26'!L9 -> 0.00715 | AG9: =N9-'Jan26'!N9 -> -0.0117 | AH9: =P9-'Jan26'!P9 -> 0.0003 | AI9: =R9-'Jan26'!R9 -> 0 | AK9: =I9-'Nov25'!I9 -> -121585762 | AL9: =I9/'Nov25'!I9-1 -> -0.075210707
F10: =J10+L10+N10+P10+R10+T10 -> 1 | H10: Porto Seguro FIRF | I10: 7913397000 | J10: =AVERAGE('Mar26'!J10,'Jan26'!J10) -> 0.3585 | K10: =+J10*$I10 -> 2.8369528e+09 | L10: =AVERAGE('Mar26'!L10,'Jan26'!L10) -> 0.366 | M10: =+L10*$I10 -> 2896303302 | N10: =AVERAGE('Mar26'!N10,'Jan26'!N10) -> 0.224 | O10: =+N10*$I10 -> 1.7726009e+09 | P10: =AVERAGE('Mar26'!P10,'Jan26'!P10) -> 0.0515 | Q10: =+P10*$I10 -> 4.0753995e+08 | R10: =AVERAGE('Mar26'!R10,'Jan26'!R10) -> 0 | S10: =+R10*$I10 -> 0 | T10: =AVERAGE('Mar26'!T10,'Jan26'!T10) -> 0 | U10: =+T10*$I10 -> 0 | Y10: =K10-'Jan26'!K10 -> 49563875 | Z10: =M10-'Jan26'!M10 -> -72700225 | AA10: =O10-'Jan26'!O10 -> 11729155 | AB10: =Q10-'Jan26'!Q10 -> 28518219 | AC10: =+S10-'Jan26'!S10 -> 0 | AE10: =J10-'Jan26'!J10 -> 0.0055 | AF10: =L10-'Jan26'!L10 -> -0.01 | AG10: =N10-'Jan26'!N10 -> 0.001 | AH10: =P10-'Jan26'!P10 -> 0.0035 | AI10: =R10-'Jan26'!R10 -> 0 | AK10: =I10-'Nov25'!I10 -> 1.4632846e+08 | AL10: =I10/'Nov25'!I10-1 -> 0.018839599
F11: =J11+L11+N11+P11+R11+T11 -> 1 | H11: Nu Reserva Imediata | I11: 2899174514 | J11: 0.59 | K11: =+J11*$I11 -> 1.710513e+09 | L11: 0.3 | M11: =+L11*$I11 -> 8.6975235e+08 | N11: 0.11 | O11: =+N11*$I11 -> 3.189092e+08 | P11: 0 | Q11: =+P11*$I11 -> 0 | R11: 0 | S11: =+R11*$I11 -> 0 | T11: 0 | U11: =+T11*$I11 -> 0 | Y11: =K11-'Jan26'!K11 -> -79127839 | Z11: =M11-'Jan26'!M11 -> 48277888 | AA11: =O11-'Jan26'!O11 -> -3812915.4 | AB11: =Q11-'Jan26'!Q11 -> 0 | AC11: =+S11-'Jan26'!S11 -> 0 | AE11: =J11-'Jan26'!J11 -> -0.02 | AF11: =L11-'Jan26'!L11 -> 0.02 | AG11: =N11-'Jan26'!N11 -> 0 | AH11: =P11-'Jan26'!P11 -> 0 | AI11: =R11-'Jan26'!R11 -> 0 | AK11: =I11-'Nov25'!I11 -> -96457175 | AL11: =I11/'Nov25'!I11-1 -> -0.032199277
