Workbook

Sheet CAPA
B2: Comparador de Fundos
B4: Fundos D+1
B5: Nome | C5: CNPJ | D5: Classificação | E5: Gestora | F5: Administradora | G5: Taxa de Adm. | H5: 46113 | I5: Acumulado | J5: Volatilidade | K5: PL Atual | L5: Início do Fundo
A6: 216658 | B6: GERAES | C6: 09.720.734/0001-10 | D6: =INDEX(Planilha2!$E:$E,MATCH(CAPA!A6,Planilha2!$D:$D,0)) -> Renda Fixa Duração Livre Grau de Investimento | E6: =INDEX(Planilha2!$F:$F,MATCH(CAPA!A6,Planilha2!$D:$D,0)) -> Af Invest Administração de Recursos Ltda | F6: =INDEX(Planilha2!$G:$G,MATCH(CAPA!A6,Planilha2!$D:$D,0)) -> BTG Pactual Servicos Financeiros S/A Dtv | G6: =INDEX(Planilha2!$H:$H,MATCH(CAPA!A6,Planilha2!$D:$D,0)) -> 0 | H6: =(_xlfn.XLOOKUP(A6,Cotas!$C$1:$C$27,Cotas!$E$1:$E$27)/_xlfn.XLOOKUP(A6,Cotas!$C$1:$C$27,Cotas!$F$1:$F$27))-1 -> 0.010127895 | I6: =(INDEX(Planilha2!$J:$J,MATCH(A6,Planilha2!$D:$D,0)))/Cotas!G11-1 -> 4.4968332 | J6: =INDEX(Planilha2!$L:$L,MATCH(CAPA!A6,Planilha2!$D:$D,0)) -> 0.63200306 | K6: =INDEX(Planilha2!$M:$M,MATCH(CAPA!A6,Planilha2!$D:$D,0)) -> 539746.11 | L6: =INDEX(Planilha2!$K:$K,MATCH(CAPA!A6,Planilha2!$D:$D,0)) -> 39702
A7: 634468 | B7: ARX Denali | C7: 41.888.219/0001-56 | D7: =INDEX(Planilha2!$E:$E,MATCH(CAPA!A7,Planilha2!$D:$D,0)) -> Renda Fixa Duração Baixa Grau de Investimento | E7: =INDEX(Planilha2!$F:$F,MATCH(CAPA!A7,Planilha2!$D:$D,0)) -> ARX Investimentos Ltda. | F7: =INDEX(Planilha2!$G:$G,MATCH(CAPA!A7,Planilha2!$D:$D,0)) -> BNY Mellon Serviços Financeiros Dtvm S/A | G7: =INDEX(Planilha2!$H:$H,MATCH(CAPA!A7,Planilha2!$D:$D,0)) -> 0 | H7: =(_xlfn.XLOOKUP(A7,Cotas!$C$1:$C$27,Cotas!$E$1:$E$27)/_xlfn.XLOOKUP(A7,Cotas!$C$1:$C$27,Cotas!$F$1:$F$27))-1 -> 0.011376612 | I7: =(INDEX(Planilha2!$J:$J,MATCH(A7,Planilha2!$D:$D,0)))/Cotas!H2-1 -> 0.7662261 | J7: =INDEX(Planilha2!$L:$L,MATCH(CAPA!A7,Planilha2!$D:$D,0)) -> 0.370749 | K7: =INDEX(Planilha2!$M:$M,MATCH(CAPA!A7,Planilha2!$D:$D,0)) -> 1598464.3 | L7: =INDEX(Planilha2!$K:$K,MATCH(CAPA!A7,Planilha2!$D:$D,0)) -> 44413
A8: 284491 | B8: Capitânia Top | C8: 13.615.411/0001-33 | D8: =INDEX(Planilha2!$E:$E,MATCH(CAPA!A8,Planilha2!$D:$D,0)) -> Renda Fixa Duração Média Crédito Livre | E8: =INDEX(Planilha2!$F:$F,MATCH(CAPA!A8,Planilha2!$D:$D,0)) -> Capitania Capital | F8: =INDEX(Planilha2!$G:$G,MATCH(CAPA!A8,Planilha2!$D:$D,0)) -> BNY Mellon Serviços Financeiros Dtvm S/A | G8: =INDEX(Planilha2!$H:$H,MATCH(CAPA!A8,Planilha2!$D:$D,0)) -> 0 | H8: =(_xlfn.XLOOKUP(A8,Cotas!$C$1:$C$27,Cotas!$E$1:$E$27)/_xlfn.XLOOKUP(A8,Cotas!$C$1:$C$27,Cotas!$F$1:$F$27))-1 -> 0.013949155 | I8: =(INDEX(Planilha2!$J:$J,MATCH(A8,Planilha2!$D:$D,0)))/Cotas!I5-1 -> 2.8310575 | J8: =INDEX(Planilha2!$L:$L,MATCH(CAPA!A8,Planilha2!$D:$D,0)) -> 0.88878195 | K8: =INDEX(Planilha2!$M:$M,MATCH(CAPA!A8,Planilha2!$D:$D,0)) -> 203260.47 | L8: =INDEX(Planilha2!$K:$K,MATCH(CAPA!A8,Planilha2!$D:$D,0)) -> 39589
A9: 531553 | B9: Riza Lotus | C9: 36.498.670/0001-27 | D9: =INDEX(Planilha2!$E:$E,MATCH(CAPA!A9,Planilha2!$D:$D,0)) -> Renda Fixa Duração Livre Grau de Investimento | E9: =INDEX(Planilha2!$F:$F,MATCH(CAPA!A9,Planilha2!$D:$D,0)) -> Riza Líquidos | F9: =INDEX(Planilha2!$G:$G,MATCH(CAPA!A9,Planilha2!$D:$D,0)) -> BTG Pactual Servicos Financeiros S/A Dtv | G9: =INDEX(Planilha2!$H:$H,MATCH(CAPA!A9,Planilha2!$D:$D,0)) -> 0.4 | H9: =(_xlfn.XLOOKUP(A9,Cotas!$C$1:$C$27,Cotas!$E$1:$E$27)/_xlfn.XLOOKUP(A9,Cotas!$C$1:$C$27,Cotas!$F$1:$F$27))-1 -> 0.010575743 | I9: =(INDEX(Planilha2!$J:$J,MATCH(A9,Planilha2!$D:$D,0)))/Cotas!J12-1 -> 0.9132096 | J9: =INDEX(Planilha2!$L:$L,MATCH(CAPA!A9,Planilha2!$D:$D,0)) -> 0.33481661 | K9: =INDEX(Planilha2!$M:$M,MATCH(CAPA!A9,Planilha2!$D:$D,0)) -> 3801596.9 | L9: =INDEX(Planilha2!$K:$K,MATCH(CAPA!A9,Planilha2!$D:$D,0)) -> 43907
A10: 489956 | B10: Western Asset Total | C10: 28.320.756/0001-37 | D10: =INDEX(Planilha2!$E:$E,MATCH(CAPA!A10,Planilha2!$D:$D,0)) -> Renda Fixa Duração Baixa Grau de Investimento | E10: =INDEX(Planilha2!$F:$F,MATCH(CAPA!A10,Planilha2!$D:$D,0)) -> Franklin Templeton Brasil Ltda | F10: =INDEX(Planilha2!$G:$G,MATCH(CAPA!A10,Planilha2!$D:$D,0)) -> Banco BNP Paribas Brasil S/A | G10: =INDEX(Planilha2!$H:$H,MATCH(CAPA!A10,Planilha2!$D:$D,0)) -> 0 | H10: =(_xlfn.XLOOKUP(A10,Cotas!$C$1:$C$27,Cotas!$E$1:$E$27)/_xlfn.XLOOKUP(A10,Cotas!$C$1:$C$27,Cotas!$F$1:$F$27))-1 -> 0.010682849 | I10: =(INDEX(Planilha2!$J:$J,MATCH(A10,Planilha2!$D:$D,0)))/Cotas!K14-1 -> 0.92662118 | J10: =INDEX(Planilha2!$L:$L,MATCH(CAPA!A10,Planilha2!$D:$D,0)) -> 0.78192199 | K10: =INDEX(Planilha2!$M:$M,MATCH(CAPA!A10,Planilha2!$D:$D,0)) -> 3569168.5 | L10: =INDEX(Planilha2!$K:$K,MATCH(CAPA!A10,Planilha2!$D:$D,0)) -> 43538
A11: 259624 | B11: Daycoval Classic | C11: 10.783.480/0001-68 | D11: =INDEX(Planilha2!$E:$E,MATCH(CAPA!A11,Planilha2!$D:$D,0)) -> Renda Fixa Duração Baixa Grau de Investimento | E11: =INDEX(Planilha2!$F:$F,MATCH(CAPA!A11,Planilha2!$D:$D,0)) -> Daycoval Asset Manag | F11: =INDEX(Planilha2!$G:$G,MATCH(CAPA!A11,Planilha2!$D:$D,0)) -> Banco Daycoval S.A. | G11: =INDEX(Planilha2!$H:$H,MATCH(CAPA!A11,Planilha2!$D:$D,0)) -> 0 | H11: =(_xlfn.XLOOKUP(A11,Cotas!$C$1:$C$27,Cotas!$E$1:$E$27)/_xlfn.XLOOKUP(A11,Cotas!$C$1:$C$27,Cotas!$F$1:$F$27))-1 -> 0.010100012 | I11: =(INDEX(Planilha2!$J:$J,MATCH(A11,Planilha2!$D:$D,0)))/Cotas!L16-1 -> 3.7860695 | J11: =INDEX(Planilha2!$L:$L,MATCH(CAPA!A11,Planilha2!$D:$D,0)) -> 0.38517713 | K11: =INDEX(Planilha2!$M:$M,MATCH(CAPA!A11,Planilha2!$D:$D,0)) -> 2164491.5 | L11: =INDEX(Planilha2!$K:$K,MATCH(CAPA!A11,Planilha2!$D:$D,0)) -> 40389
A12: 456497 | B12: Iridium Apollo | C12: 26.978.438/0001-32 | D12: =INDEX(Planilha2!$E:$E,MATCH(CAPA!A12,Planilha2!$D:$D,0)) -> Renda Fixa Duração Livre Grau de Investimento | E12: =INDEX(Planilha2!$F:$F,MATCH(CAPA!A12,Planilha2!$D:$D,0)) -> Iridium Gestão de Recursos Ltda. | F12: =INDEX(Planilha2!$G:$G,MATCH(CAPA!A12,Planilha2!$D:$D,0)) -> BNY Mellon Serviços Financeiros Dtvm S/A | G12: =INDEX(Planilha2!$H:$H,MATCH(CAPA!A12,Planilha2!$D:$D,0)) -> 0 | H12: =(_xlfn.XLOOKUP(A12,Cotas!$C$1:$C$27,Cotas!$E$1:$E$27)/_xlfn.XLOOKUP(A12,Cotas!$C$1:$C$27,Cotas!$F$1:$F$27))-1 -> 0.011990377 | I12: =(INDEX(Planilha2!$J:$J,MATCH(A12,Planilha2!$D:$D,0)))/Cotas!M18-1 -> 1.0870277 | J12: =INDEX(Planilha2!$L:$L,MATCH(CAPA!A12,Planilha2!$D:$D,0)) -> 0.88568006 | K12: =INDEX(Planilha2!$M:$M,MATCH(CAPA!A12,Planilha2!$D:$D,0)) -> 1387027 | L12: =INDEX(Planilha2!$K:$K,MATCH(CAPA!A12,Planilha2!$D:$D,0)) -> 43047
A13: 361445 | B13: Porto Seguro FIRF | C13: 18.719.154/0001-01 | D13: =INDEX(Planilha2!$E:$E,MATCH(CAPA!A13,Planilha2!$D:$D,0)) -> Renda Fixa Duração Baixa Grau de Investimento | E13: =INDEX(Planilha2!$F:$F,MATCH(CAPA!A13,Planilha2!$D:$D,0)) -> Porto Seguro Investimentos Ltda. | F13: =INDEX(Planilha2!$G:$G,MATCH(CAPA!A13,Planilha2!$D:$D,0)) -> Intrag Dist. de Títu | G13: =INDEX(Planilha2!$H:$H,MATCH(CAPA!A13,Planilha2!$D:$D,0)) -> 0 | H13: =(_xlfn.XLOOKUP(A13,Cotas!$C$1:$C$27,Cotas!$E$1:$E$27)/_xlfn.XLOOKUP(A13,Cotas!$C$1:$C$27,Cotas!$F$1:$F$27))-1 -> 0.010954673 | I13: =(INDEX(Planilha2!$J:$J,MATCH(A13,Planilha2!$D:$D,0)))/Cotas!N24-1 -> 2.3245078 | J13: =INDEX(Planilha2!$L:$L,MATCH(CAPA!A13,Planilha2!$D:$D,0)) -> 0.54447902 | K13: =INDEX(Planilha2!$M:$M,MATCH(CAPA!A13,Planilha2!$D:$D,0)) -> 6892815.2 | L13: =INDEX(Planilha2!$K:$K,MATCH(CAPA!A13,Planilha2!$D:$D,0)) -> 41698
A14: 635091 | B14: Nu Reserva Imediata | C14: 42.699.466/0001-77 | D14: =INDEX(Planilha2!$E:$E,MATCH(CAPA!A14,Planilha2!$D:$D,0)) -> Renda Fixa Duração Baixa Grau de Investimento | E14: =INDEX(Planilha2!$F:$F,MATCH(CAPA!A14,Planilha2!$D:$D,0)) -> Nu Asset Management Ltda. | F14: =INDEX(Planilha2!$G:$G,MATCH(CAPA!A14,Planilha2!$D:$D,0)) -> Intrag Dist. de Títu | G14: =INDEX(Planilha2!$H:$H,MATCH(CAPA!A14,Planilha2!$D:$D,0)) -> 0 | H14: =(_xlfn.XLOOKUP(A14,Cotas!$C$1:$C$27,Cotas!$E$1:$E$27)/_xlfn.XLOOKUP(A14,Cotas!$C$1:$C$27,Cotas!$F$1:$F$27))-1 -> 0.0099662639 | I14: =(INDEX(Planilha2!$J:$J,MATCH(A14,Planilha2!$D:$D,0)))/1-1 -> 0.6933984 | J14: =INDEX(Planilha2!$L:$L,MATCH(CAPA!A14,Planilha2!$D:$D,0)) -> 0.44668576 | K14: =INDEX(Planilha2!$M:$M,MATCH(CAPA!A14,Planilha2!$D:$D,0)) -> 2834785.7 | L14: =INDEX(Planilha2!$K:$K,MATCH(CAPA!A14,Planilha2!$D:$D,0)) -> 44574
A15: 387444 | B15: Inter Conservador | C15: 20.879.578/0001-77 | D15: =INDEX(Planilha2!$E:$E,MATCH(CAPA!A15,Planilha2!$D:$D,0)) -> Renda Fixa Duração Baixa Grau de Investimento | E15: =INDEX(Planilha2!$F:$F,MATCH(CAPA!A15,Planilha2!$D:$D,0)) -> Inter Asset | F15: =INDEX(Planilha2!$G:$G,MATCH(CAPA!A15,Planilha2!$D:$D,0)) -> Inter Distribuidora de Títulos e Valores | G15: =INDEX(Planilha2!$H:$H,MATCH(CAPA!A15,Planilha2!$D:$D,0)) -> 0 | H15: =(_xlfn.XLOOKUP(A15,Cotas!$C$1:$C$27,Cotas!$E$1:$E$27)/_xlfn.XLOOKUP(A15,Cotas!$C$1:$C$27,Cotas!$F$1:$F$27))-1 -> 0.011140631 | I15: =(INDEX(Planilha2!$J:$J,MATCH(A15,Planilha2!$D:$D,0)))/1-1 -> 1.9001288 | J15: =INDEX(Planilha2!$L:$L,MATCH(CAPA!A15,Planilha2!$D:$D,0)) -> 0.82942731 | K15: =INDEX(Planilha2!$M:$M,MATCH(CAPA!A15,Planilha2!$D:$D,0)) -> 1344300.3 | L15: =INDEX(Planilha2!$K:$K,MATCH(CAPA!A15,Planilha2!$D:$D,0)) -> 42034
A16: 677930 | B16: Absolute Atenas | C16: 48.096.589/0001-08 | D16: =INDEX(Planilha2!$E:$E,MATCH(CAPA!A16,Planilha2!$D:$D,0)) -> Renda Fixa Duração Baixa Grau de Investimento | E16: =INDEX(Planilha2!$F:$F,MATCH(CAPA!A16,Planilha2!$D:$D,0)) -> Absolute Crédito | F16: =INDEX(Planilha2!$G:$G,MATCH(CAPA!A16,Planilha2!$D:$D,0)) -> BTG Pactual Servicos Financeiros S/A Dtv | G16: =INDEX(Planilha2!$H:$H,MATCH(CAPA!A16,Planilha2!$D:$D,0)) -> 0 | H16: =(_xlfn.XLOOKUP(A16,Cotas!$C$1:$C$27,Cotas!$E$1:$E$27)/_xlfn.XLOOKUP(A16,Cotas!$C$1:$C$27,Cotas!$F$1:$F$27))-1 -> 0.0099284703 | I16: =(INDEX(Planilha2!$J:$J,MATCH(A16,Planilha2!$D:$D,0)))/1-1 -> 0.56863965 | J16: =INDEX(Planilha2!$L:$L,MATCH(CAPA!A16,Planilha2!$D:$D,0)) -> 0.26345109 | K16: =INDEX(Planilha2!$M:$M,MATCH(CAPA!A16,Planilha2!$D:$D,0)) -> 734275.08 | L16: =INDEX(Planilha2!$K:$K,MATCH(CAPA!A16,Planilha2!$D:$D,0)) -> 44862
B20: Fundos D+30
B21: Nome | C21: CNPJ | D21: Classificação | E21: Gestora | F21: Administradora | G21: Taxa de Adm. | H21: 46113 | I21: Acumulado | J21: Volatilidade | K21: PL Atual | L21: Início do Fundo
A22: 462276 | B22: Geraes 30 | C22: 29.044.189/0001-04 | D22: =INDEX(Planilha2!$E:$E,MATCH(CAPA!A22,Planilha2!$D:$D,0)) -> Renda Fixa Duração Livre Grau de Investimento | E22: =INDEX(Planilha2!$F:$F,MATCH(CAPA!A22,Planilha2!$D:$D,0)) -> Af Invest Administração de Recursos Ltda | F22: =INDEX(Planilha2!$G:$G,MATCH(CAPA!A22,Planilha2!$D:$D,0)) -> BTG Pactual Servicos Financeiros S/A Dtv | G22: =INDEX(Planilha2!$H:$H,MATCH(CAPA!A22,Planilha2!$D:$D,0)) -> 0 | H22: =(_xlfn.XLOOKUP(A22,Cotas!$C$1:$C$27,Cotas!$E$1:$E$27)/_xlfn.XLOOKUP(A22,Cotas!$C$1:$C$27,Cotas!$F$1:$F$27))-1 -> 0.0094101092 | I22: =(INDEX(Planilha2!$J:$J,MATCH(A22,Planilha2!$D:$D,0)))/1-1 -> 1.0633091 | J22: =INDEX(Planilha2!$L:$L,MATCH(CAPA!A22,Planilha2!$D:$D,0)) -> 1.101544 | K22: =INDEX(Planilha2!$M:$M,MATCH(CAPA!A22,Planilha2!$D:$D,0)) -> 311423.16 | L22: =INDEX(Planilha2!$K:$K,MATCH(CAPA!A22,Planilha2!$D:$D,0)) -> 43187
A23: 470473 | B23: Daycoval Classic 30 | C23: 29.250.121/0001-73 | D23: =INDEX(Planilha2!$E:$E,MATCH(CAPA!A23,Planilha2!$D:$D,0)) -> Renda Fixa Duração Baixa Grau de Investimento | E23: =INDEX(Planilha2!$F:$F,MATCH(CAPA!A23,Planilha2!$D:$D,0)) -> Daycoval Asset Manag | F23: =INDEX(Planilha2!$G:$G,MATCH(CAPA!A23,Planilha2!$D:$D,0)) -> Banco Daycoval S.A. | G23: =INDEX(Planilha2!$H:$H,MATCH(CAPA!A23,Planilha2!$D:$D,0)) -> 0 | H23: =(_xlfn.XLOOKUP(A23,Cotas!$C$1:$C$27,Cotas!$E$1:$E$27)/_xlfn.XLOOKUP(A23,Cotas!$C$1:$C$27,Cotas!$F$1:$F$27))-1 -> 0.010964912 | I23: =(INDEX(Planilha2!$J:$J,MATCH(A23,Planilha2!$D:$D,0)))/1-1 -> 1.1051864 | J23: =INDEX(Planilha2!$L:$L,MATCH(CAPA!A23,Planilha2!$D:$D,0)) -> 0.60675787 | K23: =INDEX(Planilha2!$M:$M,MATCH(CAPA!A23,Planilha2!$D:$D,0)) -> 865976.73 | L23: =INDEX(Planilha2!$K:$K,MATCH(CAPA!A23,Planilha2!$D:$D,0)) -> 43283
A24: 620955 | B24: Riza Lotus Plus | C24: 43.917.493/0001-31 | D24: =INDEX(Planilha2!$E:$E,MATCH(CAPA!A24,Planilha2!$D:$D,0)) -> Renda Fixa Duração Livre Grau de Investimento | E24: =INDEX(Planilha2!$F:$F,MATCH(CAPA!A24,Planilha2!$D:$D,0)) -> Riza Líquidos | F24: =INDEX(Planilha2!$G:$G,MATCH(CAPA!A24,Planilha2!$D:$D,0)) -> BTG Pactual Servicos Financeiros S/A Dtv | G24: =INDEX(Planilha2!$H:$H,MATCH(CAPA!A24,Planilha2!$D:$D,0)) -> 0 | H24: =(_xlfn.XLOOKUP(A24,Cotas!$C$1:$C$27,Cotas!$E$1:$E$27)/_xlfn.XLOOKUP(A24,Cotas!$C$1:$C$27,Cotas!$F$1:$F$27))-1 -> 0.010181018 | I24: =(INDEX(Planilha2!$J:$J,MATCH(A24,Planilha2!$D:$D,0)))/1-1 -> 0.7399199 | J24: =INDEX(Planilha2!$L:$L,MATCH(CAPA!A24,Planilha2!$D:$D,0)) -> 0.89491432 | K24: =INDEX(Planilha2!$M:$M,MATCH(CAPA!A24,Planilha2!$D:$D,0)) -> 498517.97 | L24: =INDEX(Planilha2!$K:$K,MATCH(CAPA!A24,Planilha2!$D:$D,0)) -> 44498
A25: 601462 | B25: ARX Vinson Advisory | C25: 41.888.492/0001-80 | D25: =INDEX(Planilha2!$E:$E,MATCH(CAPA!A25,Planilha2!$D:$D,0)) -> Renda Fixa Duração Baixa Grau de Investimento | E25: =INDEX(Planilha2!$F:$F,MATCH(CAPA!A25,Planilha2!$D:$D,0)) -> ARX Investimentos Ltda. | F25: =INDEX(Planilha2!$G:$G,MATCH(CAPA!A25,Planilha2!$D:$D,0)) -> BNY Mellon Serviços Financeiros Dtvm S/A | G25: =INDEX(Planilha2!$H:$H,MATCH(CAPA!A25,Planilha2!$D:$D,0)) -> 0 | H25: =(_xlfn.XLOOKUP(A25,Cotas!$C$1:$C$27,Cotas!$E$1:$E$27)/_xlfn.XLOOKUP(A25,Cotas!$C$1:$C$27,Cotas!$F$1:$F$27))-1 -> 0.011915693 | I25: =(INDEX(Planilha2!$J:$J,MATCH(A25,Planilha2!$D:$D,0)))/1-1 -> 0.7933704 | J25: =INDEX(Planilha2!$L:$L,MATCH(CAPA!A25,Planilha2!$D:$D,0)) -> 0.52976793 | K25: =INDEX(Planilha2!$M:$M,MATCH(CAPA!A25,Planilha2!$D:$D,0)) -> 1251713.9 | L25: =INDEX(Planilha2!$K:$K,MATCH(CAPA!A25,Planilha2!$D:$D,0)) -> 44393
A26: 493831 | B26: Sparta Max Advisory | C26: 32.757.330/0001-12 | D26: =INDEX(Planilha2!$E:$E,MATCH(CAPA!A26,Planilha2!$D:$D,0)) -> Renda Fixa Duração Média Crédito Livre | E26: =INDEX(Planilha2!$F:$F,MATCH(CAPA!A26,Planilha2!$D:$D,0)) -> Sparta Administradora de Recursos Ltda | F26: =INDEX(Planilha2!$G:$G,MATCH(CAPA!A26,Planilha2!$D:$D,0)) -> BNY Mellon Serviços Financeiros Dtvm S/A | G26: =INDEX(Planilha2!$H:$H,MATCH(CAPA!A26,Planilha2!$D:$D,0)) -> 0 | H26: =(_xlfn.XLOOKUP(A26,Cotas!$C$1:$C$27,Cotas!$E$1:$E$27)/_xlfn.XLOOKUP(A26,Cotas!$C$1:$C$27,Cotas!$F$1:$F$27))-1 -> 0.011867118 | I26: =(INDEX(Planilha2!$J:$J,MATCH(A26,Planilha2!$D:$D,0)))/1-1 -> 1.034299 | J26: =INDEX(Planilha2!$L:$L,MATCH(CAPA!A26,Planilha2!$D:$D,0)) -> 0.85969764 | K26: =INDEX(Planilha2!$M:$M,MATCH(CAPA!A26,Planilha2!$D:$D,0)) -> 140665.95 | L26: =INDEX(Planilha2!$K:$K,MATCH(CAPA!A26,Planilha2!$D:$D,0)) -> 43585
A27: 478008 | B27: Polo Crédito Corporativo | C27: 31.455.879/0001-90 | D27: =INDEX(Planilha2!$E:$E,MATCH(CAPA!A27,Planilha2!$D:$D,0)) -> Renda Fixa Duração Livre Crédito Livre | E27: =INDEX(Planilha2!$F:$F,MATCH(CAPA!A27,Planilha2!$D:$D,0)) -> Polo Capital Gestão de Recurso | F27: =INDEX(Planilha2!$G:$G,MATCH(CAPA!A27,Planilha2!$D:$D,0)) -> BNY Mellon Serviços Financeiros Dtvm S/A | G27: =INDEX(Planilha2!$H:$H,MATCH(CAPA!A27,Planilha2!$D:$D,0)) -> 0 | H27: =(_xlfn.XLOOKUP(A27,Cotas!$C$1:$C$27,Cotas!$E$1:$E$27)/_xlfn.XLOOKUP(A27,Cotas!$C$1:$C$27,Cotas!$F$1:$F$27))-1 -> 0.0082275174 | I27: =(INDEX(Planilha2!$J:$J,MATCH(A27,Planilha2!$D:$D,0)))/1-1 -> 1.1123136 | J27: =INDEX(Planilha2!$L:$L,MATCH(CAPA!A27,Planilha2!$D:$D,0)) -> 0.6130043 | K27: =INDEX(Planilha2!$M:$M,MATCH(CAPA!A27,Planilha2!$D:$D,0)) -> 1157810.9 | L27: =INDEX(Planilha2!$K:$K,MATCH(CAPA!A27,Planilha2!$D:$D,0)) -> 43395
A28: 494607 | B28: Iridium Titan Advisory | C28: 32.756.812/0001-58 | D28: =INDEX(Planilha2!$E:$E,MATCH(CAPA!A28,Planilha2!$D:$D,0)) -> Renda Fixa Duração Livre Crédito Livre | E28: =INDEX(Planilha2!$F:$F,MATCH(CAPA!A28,Planilha2!$D:$D,0)) -> Iridium Gestão de Recursos Ltda. | F28: =INDEX(Planilha2!$G:$G,MATCH(CAPA!A28,Planilha2!$D:$D,0)) -> BNY Mellon Serviços Financeiros Dtvm S/A | G28: =INDEX(Planilha2!$H:$H,MATCH(CAPA!A28,Planilha2!$D:$D,0)) -> 0 | H28: =(_xlfn.XLOOKUP(A28,Cotas!$C$1:$C$27,Cotas!$E$1:$E$27)/_xlfn.XLOOKUP(A28,Cotas!$C$1:$C$27,Cotas!$F$1:$F$27))-1 -> 0.012573542 | I28: =(INDEX(Planilha2!$J:$J,MATCH(A28,Planilha2!$D:$D,0)))/1-1 -> 1.0185206 | J28: =INDEX(Planilha2!$L:$L,MATCH(CAPA!A28,Planilha2!$D:$D,0)) -> 0.67011672 | K28: =INDEX(Planilha2!$M:$M,MATCH(CAPA!A28,Planilha2!$D:$D,0)) -> 187499.27 | L28: =INDEX(Planilha2!$K:$K,MATCH(CAPA!A28,Planilha2!$D:$D,0)) -> 43591
A29: 523666 | B29: Porto Seguro Ipê | C29: 35.378.376/0001-19 | D29: =INDEX(Planilha2!$E:$E,MATCH(CAPA!A29,Planilha2!$D:$D,0)) -> Renda Fixa Duração Livre Crédito Livre | E29: =INDEX(Planilha2!$F:$F,MATCH(CAPA!A29,Planilha2!$D:$D,0)) -> Porto Seguro Investimentos Ltda. | F29: =INDEX(Planilha2!$G:$G,MATCH(CAPA!A29,Planilha2!$D:$D,0)) -> Intrag Dist. de Títu | G29: =INDEX(Planilha2!$H:$H,MATCH(CAPA!A29,Planilha2!$D:$D,0)) -> 0 | H29: =(_xlfn.XLOOKUP(A29,Cotas!$C$1:$C$27,Cotas!$E$1:$E$27)/_xlfn.XLOOKUP(A29,Cotas!$C$1:$C$27,Cotas!$F$1:$F$27))-1 -> 0.011851861 | I29: =(INDEX(Planilha2!$J:$J,MATCH(A29,Planilha2!$D:$D,0)))/100-1 -> 0.94542516 | J29: =INDEX(Planilha2!$L:$L,MATCH(CAPA!A29,Planilha2!$D:$D,0)) -> 0.70542075 | K29: =INDEX(Planilha2!$M:$M,MATCH(CAPA!A29,Planilha2!$D:$D,0)) -> 535325.15 | L29: =INDEX(Planilha2!$K:$K,MATCH(CAPA!A29,Planilha2!$D:$D,0)) -> 43798
A30: 494089 | B30: Sparta Top Advisory | C30: 32.846.811/0001-02 | D30: =INDEX(Planilha2!$E:$E,MATCH(CAPA!A30,Planilha2!$D:$D,0)) -> Renda Fixa Duração Média Grau de Investimento | E30: =INDEX(Planilha2!$F:$F,MATCH(CAPA!A30,Planilha2!$D:$D,0)) -> Sparta Administradora de Recursos Ltda | F30: =INDEX(Planilha2!$G:$G,MATCH(CAPA!A30,Planilha2!$D:$D,0)) -> BNY Mellon Serviços Financeiros Dtvm S/A | G30: =INDEX(Planilha2!$H:$H,MATCH(CAPA!A30,Planilha2!$D:$D,0)) -> 0 | H30: =(_xlfn.XLOOKUP(A30,Cotas!$C$1:$C$27,Cotas!$E$1:$E$27)/_xlfn.XLOOKUP(A30,Cotas!$C$1:$C$27,Cotas!$F$1:$F$27))-1 -> 0.010831797 | I30: =(INDEX(Planilha2!$J:$J,MATCH(A30,Planilha2!$D:$D,0)))/1-1 -> 0.94383778 | J30: =INDEX(Planilha2!$L:$L,MATCH(CAPA!A30,Planilha2!$D:$D,0)) -> 0.83844845 | K30: =INDEX(Planilha2!$M:$M,MATCH(CAPA!A30,Planilha2!$D:$D,0)) -> 574548.93 | L30: =INDEX(Planilha2!$K:$K,MATCH(CAPA!A30,Planilha2!$D:$D,0)) -> 43579
A31: 678007 | B31: Absolute Creta | C31: 48.122.126/0001-65 | D31: =INDEX(Planilha2!$E:$E,MATCH(CAPA!A31,Planilha2!$D:$D,0)) -> Renda Fixa Duração Baixa Grau de Investimento | E31: =INDEX(Planilha2!$F:$F,MATCH(CAPA!A31,Planilha2!$D:$D,0)) -> Absolute Crédito | F31: =INDEX(Planilha2!$G:$G,MATCH(CAPA!A31,Planilha2!$D:$D,0)) -> BTG Pactual Servicos Financeiros S/A Dtv | G31: =INDEX(Planilha2!$H:$H,MATCH(CAPA!A31,Planilha2!$D:$D,0)) -> 0 | H31: =(_xlfn.XLOOKUP(A31,Cotas!$C$1:$C$27,Cotas!$E$1:$E$27)/_xlfn.XLOOKUP(A31,Cotas!$C$1:$C$27,Cotas!$F$1:$F$27))-1 -> 0.0083405799 | I31: =(INDEX(Planilha2!$J:$J,MATCH(A31,Planilha2!$D:$D,0)))/1-1 -> 0.58598776 | J31: =INDEX(Planilha2!$L:$L,MATCH(CAPA!A31,Planilha2!$D:$D,0)) -> 0.4832305 | K31: =INDEX(Planilha2!$M:$M,MATCH(CAPA!A31,Planilha2!$D:$D,0)) -> 1721026.5 | L31: =INDEX(Planilha2!$K:$K,MATCH(CAPA!A31,Planilha2!$D:$D,0)) -> 44862
B35: Fundos D+60
B36: Nome | C36: CNPJ | D36: Classificação | E36: Gestora | F36: Administradora | G36: Taxa de Adm. | H36: 46113 | I36: Acumulado | J36: Volatilidade | K36: PL Atual | L36: Início do Fundo
A37: 624977 | B37: Horizonte | C37: 44.025.131/0001-07 | D37: =INDEX(Planilha2!$E:$E,MATCH(CAPA!A37,Planilha2!$D:$D,0)) -> Multimercados Livre | E37: =INDEX(Planilha2!$F:$F,MATCH(CAPA!A37,Planilha2!$D:$D,0)) -> Af Invest Administração de Recursos Ltda | F37: =INDEX(Planilha2!$G:$G,MATCH(CAPA!A37,Planilha2!$D:$D,0)) -> BTG Pactual Servicos Financeiros S/A Dtv | G37: =INDEX(Planilha2!$H:$H,MATCH(CAPA!A37,Planilha2!$D:$D,0)) -> 0 | H37: =(_xlfn.XLOOKUP(A37,Cotas!$C$1:$C$27,Cotas!$E$1:$E$27)/_xlfn.XLOOKUP(A37,Cotas!$C$1:$C$27,Cotas!$F$1:$F$27))-1 -> 0.01076937 | I37: =(INDEX(Planilha2!$J:$J,MATCH(A37,Planilha2!$D:$D,0)))/1-1 -> 0.7252344 | J37: =INDEX(Planilha2!$L:$L,MATCH(CAPA!A37,Planilha2!$D:$D,0)) -> 0.91291145 | K37: =INDEX(Planilha2!$M:$M,MATCH(CAPA!A37,Planilha2!$D:$D,0)) -> 230557.05 | L37: =INDEX(Planilha2!$K:$K,MATCH(CAPA!A37,Planilha2!$D:$D,0)) -> 44523
A38: 393185 | B38: JGP Select | C38: 21.946.695/0001-79 | D38: =INDEX(Planilha2!$E:$E,MATCH(CAPA!A38,Planilha2!$D:$D,0)) -> Multimercados Estratégia Específica | E38: =INDEX(Planilha2!$F:$F,MATCH(CAPA!A38,Planilha2!$D:$D,0)) -> Jgp Gestão de Crédito Ltda. | F38: =INDEX(Planilha2!$G:$G,MATCH(CAPA!A38,Planilha2!$D:$D,0)) -> BNY Mellon Serviços Financeiros Dtvm S/A | G38: =INDEX(Planilha2!$H:$H,MATCH(CAPA!A38,Planilha2!$D:$D,0)) -> 0 | H38: =(_xlfn.XLOOKUP(A38,Cotas!$C$1:$C$27,Cotas!$E$1:$E$27)/_xlfn.XLOOKUP(A38,Cotas!$C$1:$C$27,Cotas!$F$1:$F$27))-1 -> 0.010999159 | I38: =(INDEX(Planilha2!$J:$J,MATCH(A38,Planilha2!$D:$D,0)))/100-1 -> 2.2129301 | J38: =INDEX(Planilha2!$L:$L,MATCH(CAPA!A38,Planilha2!$D:$D,0)) -> 1.5295323 | K38: =INDEX(Planilha2!$M:$M,MATCH(CAPA!A38,Planilha2!$D:$D,0)) -> 347114.09 | L38: =INDEX(Planilha2!$K:$K,MATCH(CAPA!A38,Planilha2!$D:$D,0)) -> 42118
A39: 526886 | B39: ARX Everest Advisory | C39: 35.789.436/0001-96 | D39: =INDEX(Planilha2!$E:$E,MATCH(CAPA!A39,Planilha2!$D:$D,0)) -> Renda Fixa Duração Baixa Grau de Investimento | E39: =INDEX(Planilha2!$F:$F,MATCH(CAPA!A39,Planilha2!$D:$D,0)) -> ARX Investimentos Ltda. | F39: =INDEX(Planilha2!$G:$G,MATCH(CAPA!A39,Planilha2!$D:$D,0)) -> BNY Mellon Serviços Financeiros Dtvm S/A | G39: =INDEX(Planilha2!$H:$H,MATCH(CAPA!A39,Planilha2!$D:$D,0)) -> 0 | H39: =(_xlfn.XLOOKUP(A39,Cotas!$C$1:$C$27,Cotas!$E$1:$E$27)/_xlfn.XLOOKUP(A39,Cotas!$C$1:$C$27,Cotas!$F$1:$F$27))-1 -> 0.012434786 | I39: =(INDEX(Planilha2!$J:$J,MATCH(A39,Planilha2!$D:$D,0)))/1-1 -> 0.94181722 | J39: =INDEX(Planilha2!$L:$L,MATCH(CAPA!A39,Planilha2!$D:$D,0)) -> 1.0987365 | K39: =INDEX(Planilha2!$M:$M,MATCH(CAPA!A39,Planilha2!$D:$D,0)) -> 424848.58 | L39: =INDEX(Planilha2!$K:$K,MATCH(CAPA!A39,Planilha2!$D:$D,0)) -> 43866
A40: 414972 | B40: Polo Total | C40: 23.601.467/0001-92 | D40: =INDEX(Planilha2!$E:$E,MATCH(CAPA!A40,Planilha2!$D:$D,0)) -> Multimercados Livre | E40: =INDEX(Planilha2!$F:$F,MATCH(CAPA!A40,Planilha2!$D:$D,0)) -> Polo Capital Gestão de Recurso | F40: =INDEX(Planilha2!$G:$G,MATCH(CAPA!A40,Planilha2!$D:$D,0)) -> BNY Mellon Serviços Financeiros Dtvm S/A | G40: =INDEX(Planilha2!$H:$H,MATCH(CAPA!A40,Planilha2!$D:$D,0)) -> 0 | H40: =(_xlfn.XLOOKUP(A40,Cotas!$C$1:$C$27,Cotas!$E$1:$E$27)/_xlfn.XLOOKUP(A40,Cotas!$C$1:$C$27,Cotas!$F$1:$F$27))-1 -> 0.010883758 | I40: =(INDEX(Planilha2!$J:$J,MATCH(A40,Planilha2!$D:$D,0)))/1-1 -> 2.2810512 | J40: =INDEX(Planilha2!$L:$L,MATCH(CAPA!A40,Planilha2!$D:$D,0)) -> 3.2466781 | K40: =INDEX(Planilha2!$M:$M,MATCH(CAPA!A40,Planilha2!$D:$D,0)) -> 73457.618 | L40: =INDEX(Planilha2!$K:$K,MATCH(CAPA!A40,Planilha2!$D:$D,0)) -> 42432
A41: 687138 | B41: Absolute Olimpia | C41: 48.986.106/0001-32 | D41: =INDEX(Planilha2!$E:$E,MATCH(CAPA!A41,Planilha2!$D:$D,0)) -> Multimercados Livre | E41: =INDEX(Planilha2!$F:$F,MATCH(CAPA!A41,Planilha2!$D:$D,0)) -> Absolute Crédito | F41: =INDEX(Planilha2!$G:$G,MATCH(CAPA!A41,Planilha2!$D:$D,0)) -> BTG Pactual Servicos Financeiros S/A Dtv | G41: =INDEX(Planilha2!$H:$H,MATCH(CAPA!A41,Planilha2!$D:$D,0)) -> 0 | H41: =(_xlfn.XLOOKUP(A41,Cotas!$C$1:$C$27,Cotas!$E$1:$E$27)/_xlfn.XLOOKUP(A41,Cotas!$C$1:$C$27,Cotas!$F$1:$F$27))-1 -> 0.0066569517 | I41: =(INDEX(Planilha2!$J:$J,MATCH(A41,Planilha2!$D:$D,0)))/1-1 -> 0.583209 | J41: =INDEX(Planilha2!$L:$L,MATCH(CAPA!A41,Planilha2!$D:$D,0)) -> 0.61119382 | K41: =INDEX(Planilha2!$M:$M,MATCH(CAPA!A41,Planilha2!$D:$D,0)) -> 272263.43 | L41: =INDEX(Planilha2!$K:$K,MATCH(CAPA!A41,Planilha2!$D:$D,0)) -> 44925

Sheet Cotas
B1: {=_xll.ECONOMATICA(_xll.EcoRange(1,-1,26,-1),"Name",,,,,,,"false","true")} -> Nome | C1: {=_xll.ECONOMATICA(_xll.EcoRange(1,-2,26,-2),"Codigo de Fundo CVM 555/2014",,,,,,,"false","true")} -> Codigo de Fundo CVM 555/2014 | D1: {=_xll.ECONOMATICA(_xll.EcoRange(1,-3,26,-3),"Close",,"D-0",,,"ORIGINAL CURRENCY",,"false","true","Cota em reais",{"tc.pers=3"})} -> Cota em reais | E1: {=_xll.ECONOMATICA(_xll.EcoRange(1,-4,26,-4),"Close",,"2026-04-30",,,"ORIGINAL CURRENCY",,"false","true")} -> Fechamento 30Abr26 ajust p/ prov Em moeda orig | F1: {=_xll.ECONOMATICA(_xll.EcoRange(1,-5,26,-5),"Close",,"2026-03-31",,,"ORIGINAL CURRENCY",,"false","true")} -> Fechamento 31Mar26 ajust p/ prov Em moeda orig | G1: {=_xll.ECONOMATICA(_xll.EcoRange(1,-6,26,-6),"Close",,"2008-09-11",,,"ORIGINAL CURRENCY",,"false","true")} -> Fechamento 11Set08 ajust p/ prov Em moeda orig | H1: {=_xll.ECONOMATICA(_xll.EcoRange(1,-7,26,-7),"Close",,"2021-08-05",,,"ORIGINAL CURRENCY",,"false","true")} -> Fechamento 05Ago21 ajust p/ prov Em moeda orig | I1: {=_xll.ECONOMATICA(_xll.EcoRange(1,-8,26,-8),"Close",,"2011-08-22",,,"ORIGINAL CURRENCY",,"false","true")} -> Fechamento 22Ago11 ajust p/ prov Em moeda orig | J1: {=_xll.ECONOMATICA(_xll.EcoRange(1,-9,26,-9),"Close",,"2020-03-17",,,"ORIGINAL CURRENCY",,"false","true")} -> Fechamento 17Mar20 ajust p/ prov Em moeda orig | K1: {=_xll.ECONOMATICA(_xll.EcoRange(1,-10,26,-10),"Close",,"2019-03-14",,,"ORIGINAL CURRENCY",,"false","true")} -> Fechamento 14Mar19 ajust p/ prov Em moeda orig | L1: {=_xll.ECONOMATICA(_xll.EcoRange(1,-11,26,-11),"Close",,"2010-07-30",,,"ORIGINAL CURRENCY",,"false","true")} -> Fechamento 30Jul10 ajust p/ prov Em moeda orig | M1: {=_xll.ECONOMATICA(_xll.EcoRange(1,-12,26,-12),"Close",,"2017-11-08",,,"ORIGINAL CURRENCY",,"false","true")} -> Fechamento 08Nov17 ajust p/ prov Em moeda orig | N1: {=_xll.ECONOMATICA(_xll.EcoRange(1,-13,26,-13),"Close",,"2014-02-28",,,"ORIGINAL CURRENCY",,"false","true")} -> Fechamento 28Fev14 ajust p/ prov Em moeda orig | O1: {=_xll.ECONOMATICA(_xll.EcoRange(1,-14,26,-14),"Close",,"2022-01-13",,,"ORIGINAL CURRENCY",,"false","true")} -> Fechamento 13Jan22 ajust p/ prov Em moeda orig | P1: {=_xll.ECONOMATICA(_xll.EcoRange(1,-15,26,-15),"Close",,"2015-01-30",,,"ORIGINAL CURRENCY",,"false","true")} -> Fechamento 30Jan15 ajust p/ prov Em moeda orig | Q1: {=_xll.ECONOMATICA(_xll.EcoRange(1,-16,26,-16),"Close",,"2022-10-28",,,"ORIGINAL CURRENCY",,"false","true")} -> Fechamento 28Out22 ajust p/ prov Em moeda orig | R1: {=_xll.ECONOMATICA(_xll.EcoRange(1,-17,26,-17),"Close",,"2018-03-28",,,"ORIGINAL CURRENCY",,"false","true")} -> Fechamento 28Mar18 ajust p/ prov Em moeda orig | S1: {=_xll.ECONOMATICA(_xll.EcoRange(1,-18,26,-18),"Close",,"2018-07-02",,,"ORIGINAL CURRENCY",,"false","true")} -> Fechamento 02Jul18 ajust p/ prov Em moeda orig | T1: {=_xll.ECONOMATICA(_xll.EcoRange(1,-19,26,-19),"Close",,"2021-10-29",,,"ORIGINAL CURRENCY",,"false","true")} -> Fechamento 29Out21 ajust p/ prov Em moeda orig | U1: {=_xll.ECONOMATICA(_xll.EcoRange(1,-20,26,-20),"Close",,"2021-07-16",,,"ORIGINAL CURRENCY",,"false","true")} -> Fechamento 16Jul21 ajust p/ prov Em moeda orig | V1: {=_xll.ECONOMATICA(_xll.EcoRange(1,-21,26,-21),"Close",,"2019-04-30",,,"ORIGINAL CURRENCY",,"false","true")} -> Fechamento 30Abr19 ajust p/ prov Em moeda orig | W1: {=_xll.ECONOMATICA(_xll.EcoRange(1,-22,26,-22),"Close",,"2018-10-22",,,"ORIGINAL CURRENCY",,"false","true")} -> Fechamento 22Out18 ajust p/ prov Em moeda orig | X1: {=_xll.ECONOMATICA(_xll.EcoRange(1,-23,26,-23),"Close",,"2019-05-06",,,"ORIGINAL CURRENCY",,"false","true")} -> Fechamento 06Mai19 ajust p/ prov Em moeda orig | Y1: {=_xll.ECONOMATICA(_xll.EcoRange(1,-24,26,-24),"Close",,"2019-11-29",,,"ORIGINAL CURRENCY",,"false","true")} -> Fechamento 29Nov19 ajust p/ prov Em moeda orig | Z1: {=_xll.ECONOMATICA(_xll.EcoRange(1,-25,26,-25),"Close",,"2019-04-24",,,"ORIGINAL CURRENCY",,"false","true")} -> Fechamento 24Abr19 ajust p/ prov Em moeda orig | AA1: {=_xll.ECONOMATICA(_xll.EcoRange(1,-26,26,-26),"Close",,"2022-10-28",,,"ORIGINAL CURRENCY",,"false","true")} -> Fechamento 28Out22 ajust p/ prov Em moeda orig | AB1: {=_xll.ECONOMATICA(_xll.EcoRange(1,-27,26,-27),"Close",,"2021-11-23",,,"ORIGINAL CURRENCY",,"false","true")} -> Fechamento 23Nov21 ajust p/ prov Em moeda orig | AC1: {=_xll.ECONOMATICA(_xll.EcoRange(1,-28,26,-28),"Close",,"2015-04-24",,,"ORIGINAL CURRENCY",,"false","true")} -> Fechamento 24Abr15 ajust p/ prov Em moeda orig | AD1: {=_xll.ECONOMATICA(_xll.EcoRange(1,-29,26,-29),"Close",,"2020-02-05",,,"ORIGINAL CURRENCY",,"false","true")} -> Fechamento 05Fev20 ajust p/ prov Em moeda orig | AE1: {=_xll.ECONOMATICA(_xll.EcoRange(1,-30,26,-30),"Close",,"2016-03-03",,,"ORIGINAL CURRENCY",,"false","true")} -> Fechamento 03Mar16 ajust p/ prov Em moeda orig | AF1: {=_xll.ECONOMATICA(_xll.EcoRange(1,-31,26,-31),"Close",,"2022-12-30",,,"ORIGINAL CURRENCY",,"false","true")} -> Fechamento 30Dez22 ajust p/ prov Em moeda orig
A2: 634468<BraNa> | B2: ARX Denali Advisory Fc FIF RF Créd Priv - Resp Lim | C2: 634468 | D2: 1.7662261 | E2: 1.7596242 | F2: 1.7398308 | H2: 1 | O2: 1.03784 | Q2: 1.1479735 | T2: 1.0187029 | AA2: 1.1479735 | AB2: 1.0242116 | AF2: 1.1747173
A3: 526886<BraNa> | B3: ARX Everest Advisory Fc FIF RF Cred Priv - Resp Limitada | C3: 526886 | D3: 1.9418172 | E3: 1.9328767 | F3: 1.909137 | H3: 1.0852229 | J3: 1.0041849 | O3: 1.1345051 | Q3: 1.2711617 | T3: 1.1121076 | U3: 1.0810026 | AA3: 1.2711617 | AB3: 1.1187369 | AD3: 1 | AF3: 1.3038299
A4: 601462<BraNa> | B4: ARX Vinson Adv Fc FIF RF Cred Priv - Resp Limitada | C4: 601462 | D4: 1.7933704 | E4: 1.7857214 | F4: 1.7646938 | H4: 1.0041692 | O4: 1.0455768 | Q4: 1.1633393 | T4: 1.0265266 | U4: 1 | AA4: 1.1633393 | AB4: 1.0322547 | AF4: 1.1915017
A5: 284491<BraNa> | B5: Capitânia Top Cred Priv Fc FIF RF - Resp Limitada | C5: 284491 | D5: 5.3371224 | E5: 5.3329019 | F5: 5.2595358 | G5: 1.0376291 | H5: 3.2774151 | I5: 1.3931199 | J5: 3.1445395 | K5: 2.9588625 | L5: 1.2444763 | M5: 2.7140413 | N5: 1.7445266 | O5: 3.389947 | P5: 1.927868 | Q5: 3.7506474 | R5: 2.7831627 | S5: 2.8307033 | T5: 3.3261074 | U5: 3.2723491 | V5: 2.9901916 | W5: 2.8903311 | X5: 2.9959838 | Y5: 3.1011553 | Z5: 2.98809 | AA5: 3.7506474 | AB5: 3.3408209 | AC5: 1.9818129 | AD5: 3.1440475 | AE5: 2.222434 | AF5: 3.8267769
A6: 677930<BraNa> | B6: Classe Única de Cotas do Absolute Atenas Advisory FI Financeiro em Cota | C6: 677930 | D6: 1.5686397 | E6: 1.5629491 | F6: 1.5475839 | Q6: 1 | AA6: 1 | AF6: 1.0253053
A7: 678007<BraNa> | B7: Classe Única de Cotas do Absolute Creta Advisory F | C7: 678007 | D7: 1.5859878 | E7: 1.5783773 | F7: 1.5653216 | Q7: 1 | AA7: 1 | AF7: 1.0264306
A8: 687138<BraNa> | B8: Classe Única de Cotas do Absolute Olimpia Fundo de | C8: 687138 | D8: 1.583209 | E8: 1.5746727 | F8: 1.5642595 | AF8: 1
A9: 624977<BraNa> | B9: Classe Unica de Cotas do Af Horizonte Fundo de Inv | C9: 624977 | D9: 1.7252344 | E9: 1.7186055 | F9: 1.7002944 | O9: 1.0147108 | Q9: 1.1318189 | AA9: 1.1318189 | AB9: 1 | AF9: 1.1627989
A10: 462276<BraNa> | B10: Classe Única de Cotas do Af Invest Geraes 30 FI Financeiro RF - | C10: 462276 | D10: 2.0633091 | E10: 2.0579606 | F10: 2.0387755 | H10: 1.1603029 | J10: 1.1432 | K10: 1.0810049 | O10: 1.2125659 | Q10: 1.3521019 | R10: 1 | S10: 1.0211474 | T10: 1.1890657 | U10: 1.1557507 | V10: 1.0918319 | W10: 1.046623 | X10: 1.0928351 | Y10: 1.1298742 | Z10: 1.0906562 | AA10: 1.3521019 | AB10: 1.1945714 | AD10: 1.1399037 | AF10: 1.3857632
A11: 216658<BraNa> | B11: Classe Única de Cotas do Af Invest Geraes FI Financeiro RF - Cr | C11: 216658 | D11: 5.4968332 | E11: 5.4794122 | F11: 5.4244737 | G11: 1 | H11: 3.1170978 | I11: 1.3531213 | J11: 3.1129841 | K11: 2.9505964 | L11: 1.2034764 | M11: 2.6776805 | N11: 1.6936277 | O11: 3.2399192 | P11: 1.8739934 | Q11: 3.587904 | R11: 2.7565564 | S11: 2.8081113 | T11: 3.176071 | U11: 3.1085499 | V11: 2.9767967 | W11: 2.8698934 | X11: 2.9791148 | Y11: 3.0766021 | Z11: 2.9736519 | AA11: 3.587904 | AB11: 3.1936204 | AC11: 1.9262156 | AD11: 3.1029164 | AE11: 2.1605678 | AF11: 3.6723392
A12: 531553<BraNa> | B12: Classe Única de Cotas do Riza Lotus Fundo de Inves | C12: 531553 | D12: 1.9132096 | E12: 1.9068678 | F12: 1.8869123 | H12: 1.0690978 | J12: 1 | O12: 1.1075429 | Q12: 1.2279518 | T12: 1.0869528 | U12: 1.0658752 | AA12: 1.2279518 | AB12: 1.0923853 | AF12: 1.2570698
A13: 620955<BraNa> | B13: Classe Única de Cotas do Riza Lotus Plus Advisory | C13: 620955 | D13: 1.7399199 | E13: 1.7336763 | F13: 1.7162036 | O13: 1.0192348 | Q13: 1.1402935 | T13: 1 | AA13: 1.1402935 | AB13: 1.0047928 | AF13: 1.167346
A14: 489956<BraNa> | B14: Classe Única do Western Asset Total Credit Advisory FIC de Fund | C14: 489956 | D14: 1926.6212 | E14: 1919.9762 | F14: 1899.6821 | H14: 1098.5341 | J14: 1050.4205 | K14: 1000 | O14: 1138.1354 | Q14: 1254.2617 | T14: 1118.1654 | U14: 1094.6379 | V14: 1008.3999 | X14: 1009.1107 | Y14: 1040.2909 | Z14: 1007.3807 | AA14: 1254.2617 | AB14: 1123.57 | AD14: 1048.5353 | AF14: 1283.2574
A15: 470473<BraNa> | B15: Daycoval Classic 30 Classe de Investimento RF Cred Priv Resp Limitada | C15: 470473 | D15: 2.1051864 | E15: 2.096794 | F15: 2.0740522 | H15: 1.167166 | J15: 1.1114943 | K15: 1.0511561 | O15: 1.2154212 | Q15: 1.35428 | S15: 1 | T15: 1.1928621 | U15: 1.1631933 | V15: 1.0606729 | W15: 1.0219334 | X15: 1.0615014 | Y15: 1.0981563 | Z15: 1.059439 | AA15: 1.35428 | AB15: 1.199012 | AD15: 1.1075018 | AF15: 1.3874848
A16: 259624<BraNa> | B16: Daycoval Classic Classe de Investimento em Cotas de FI RF Cred Priv Resp Limitada Cred Pri | C16: 259624 | D16: 5.3789138 | E16: 5.3594202 | F16: 5.3058312 | H16: 3.0086899 | I16: 1.2705581 | J16: 2.9012443 | K16: 2.7515541 | L16: 1.1238687 | M16: 2.5120232 | N16: 1.5960995 | O16: 3.1337198 | P16: 1.7675141 | Q16: 3.4707498 | R16: 2.5805977 | S16: 2.6260887 | T16: 3.0763409 | U16: 3.0002828 | V16: 2.7754854 | W16: 2.6808647 | X16: 2.7776527 | Y16: 2.8677603 | Z16: 2.772409 | AA16: 3.4707498 | AB16: 3.0929515 | AC16: 1.815986 | AD16: 2.8920333 | AE16: 2.0424795 | AF16: 3.5525322
A17: 387444<BraNa> | B17: Inter Conservador FI Financeiro RF Cred Priv Responsabili | C17: 387444 | D17: 2.9001288 | E17: 2.890326 | F17: 2.8584807 | H17: 1.6404836 | J17: 1.6397131 | K17: 1.5599019 | M17: 1.41946 | O17: 1.7175551 | P17: 1 | Q17: 1.9025287 | R17: 1.4603639 | S17: 1.4858081 | T17: 1.6854669 | U17: 1.6363924 | V17: 1.5739439 | W17: 1.5168075 | X17: 1.5751644 | Y17: 1.6208548 | Z17: 1.5720385 | AA17: 1.9025287 | AB17: 1.6944535 | AC17: 1.0281902 | AD17: 1.6342917 | AE17: 1.1511147 | AF17: 1.9467134
A18: 456497<BraNa> | B18: Iridium Apollo Fc FIF RF Cred Priv LP - Resp Limitada | C18: 456497 | D18: 2.0870277 | E18: 2.0789638 | F18: 2.0543316 | H18: 1.1705748 | J18: 1.1557277 | K18: 1.0956521 | M18: 1 | O18: 1.2188151 | Q18: 1.3518119 | R18: 1.0263257 | S18: 1.0447617 | T18: 1.1960899 | U18: 1.1671358 | V18: 1.1048857 | W18: 1.0679714 | X18: 1.1057342 | Y18: 1.1418903 | Z18: 1.1037424 | AA18: 1.3518119 | AB18: 1.2025499 | AD18: 1.1521682 | AF18: 1.3827569
A19: 494607<BraNa> | B19: Iridium Titan Advisory Fc FIF RF Cred Priv ? Resp Limitada | C19: 494607 | D19: 2.0185206 | E19: 2.0097619 | F19: 1.9848059 | H19: 1.1105647 | J19: 1.0599083 | O19: 1.1580956 | Q19: 1.294147 | T19: 1.1337464 | U19: 1.1085087 | X19: 1 | Y19: 1.04438 | AA19: 1.294147 | AB19: 1.140574 | AD19: 1.0556855 | AF19: 1.3247278
A20: 393185<BraNa> | B20: Jgp Select Fc FIF Mult Cred Priv - Resp Limitada | C20: 393185 | D20: 321.29301 | E20: 320.05517 | F20: 316.57313 | H20: 176.1598 | J20: 161.29744 | K20: 160.75708 | M20: 145.92255 | O20: 181.24742 | Q20: 200.9787 | R20: 150.09619 | S20: 151.29689 | T20: 178.3181 | U20: 175.57956 | V20: 162.48553 | W20: 155.36069 | X20: 162.70294 | Y20: 169.18064 | Z20: 162.32214 | AA20: 200.9787 | AB20: 178.96141 | AC20: 100 | AD20: 171.83371 | AE20: 111.57078 | AF20: 206.15913
A21: 635091<BraNa> | B21: Nu Reserva Imediata FIF Cic RF Ref DI Resp Limitad | C21: 635091 | D21: 1.6933984 | E21: 1.6876813 | F21: 1.6710274 | O21: 1 | Q21: 1.1052 | AA21: 1.1052 | AF21: 1.1303088
A22: 478008<BraNa> | B22: Polo Crédito Corporativo Advisory Fc FIF RF Cred Priv LP - Resp Limitada | C22: 478008 | D22: 2.1123136 | E22: 2.1027397 | F22: 2.0855805 | H22: 1.1466894 | J22: 1.0902718 | K22: 1.0287687 | O22: 1.1908956 | Q22: 1.3287863 | T22: 1.1668217 | U22: 1.1430366 | V22: 1.0381126 | W22: 1 | X22: 1.0392395 | Y22: 1.0757625 | Z22: 1.0369996 | AA22: 1.3287863 | AB22: 1.1729875 | AD22: 1.085636 | AF22: 1.3635508
A23: 414972<BraNa> | B23: Polo Total Credit Fc FIF Mult Cred Priv - Resp Limitada | C23: 414972 | D23: 3.2810512 | E23: 3.2609409 | F23: 3.2258317 | H23: 1.7824117 | J23: 1.755066 | K23: 1.7681083 | M23: 1.5789675 | O23: 1.8446641 | Q23: 2.0312108 | R23: 1.6277879 | S23: 1.6215153 | T23: 1.8112538 | U23: 1.7745306 | V23: 1.7703122 | W23: 1.6819346 | X23: 1.768787 | Y23: 1.8005517 | Z23: 1.7742308 | AA23: 2.0312108 | AB23: 1.8110253 | AD23: 1.8468588 | AE23: 1 | AF23: 2.1155798
A24: 361445<BraNa> | B24: Porto Seguro FIF RF Ref DI Créd Priv Resp Limitada | C24: 361445 | D24: 3.3245078 | E24: 3.3118774 | F24: 3.27599 | H24: 1.8674479 | J24: 1.783959 | K24: 1.6998689 | M24: 1.5611625 | N24: 1 | O24: 1.9342799 | P24: 1.1068634 | Q24: 2.1324501 | R24: 1.600364 | S24: 1.626039 | T24: 1.9009911 | U24: 1.8611794 | V24: 1.7133436 | W24: 1.6576105 | X24: 1.7145569 | Y24: 1.7664313 | Z24: 1.7116829 | AA24: 2.1324501 | AB24: 1.9098298 | AC24: 1.1369556 | AD24: 1.7787758 | AE24: 1.2748607 | AF24: 2.1822407
A25: 523666<BraNa> | B25: Porto Seguro Ipê FIF da Cic RF Créd Priv LP Resp Limitada | C25: 523666 | D25: 194.54252 | E25: 193.73479 | F25: 191.46556 | H25: 106.89639 | J25: 101.31827 | O25: 111.13695 | Q25: 123.18813 | T25: 109.12749 | U25: 106.53933 | Y25: 100 | AA25: 123.18813 | AB25: 109.61703 | AD25: 100.99835 | AF25: 126.20597
A26: 493831<BraNa> | B26: Sparta Max Advisory Fc FIF RF Cred Priv LP - Resp Limitada | C26: 493831 | D26: 2.034299 | E26: 2.0268092 | F26: 2.0030389 | H26: 1.1237128 | J26: 1.0543433 | O26: 1.1687045 | Q26: 1.3012804 | T26: 1.1451667 | U26: 1.1186403 | V26: 1 | X26: 1.0008348 | Y26: 1.0377731 | AA26: 1.3012804 | AB26: 1.152018 | AD26: 1.0493124 | AF26: 1.3317299
A27: 494089<BraNa> | B27: Sparta Top Adv Fc FI RF Cred Priv LP - Resp Limitada | C27: 494089 | D27: 1.9438378 | E27: 1.937052 | F27: 1.9162951 | H27: 1.0902237 | J27: 1.0410712 | O27: 1.1325748 | Q27: 1.256001 | T27: 1.1112434 | U27: 1.0858749 | V27: 1.0010016 | X27: 1.0018592 | Y27: 1.0296385 | Z27: 1 | AA27: 1.256001 | AB27: 1.1173087 | AD27: 1.0389817 | AF27: 1.2844498

Sheet Planilha2
B1: {=_xll.ECONOMATICA(_xll.EcoRange(1,-1,26,-1),"Name",,,,,,,"false","true")} -> Nome | C1: {=_xll.ECONOMATICA(_xll.EcoRange(1,-2,26,-2),"Employer ID number",,,,,,,"false","true")} -> CNPJ | D1: {=_xll.ECONOMATICA(_xll.EcoRange(1,-3,26,-3),"Ticker",,,,,,,"false","true","Código Anbima")} -> Código Anbima | E1: {=_xll.ECONOMATICA(_xll.EcoRange(1,-4,26,-4),"Anbima classification",,,,,,,"false","true")} -> Classificação Anbima | F1: {=_xll.ECONOMATICA(_xll.EcoRange(1,-5,26,-5),"Fund manager",,,,,,,"false","true","Gestora ")} -> Gestora | G1: {=_xll.ECONOMATICA(_xll.EcoRange(1,-6,26,-6),"Administrator",,,,,,,"false","true")} -> Administradora | H1: {=_xll.ECONOMATICA(_xll.EcoRange(1,-7,26,-7),"Max management fee %/year",,,,,,,"false","true","Taxa de Administração Máxima em % a.a.")} -> Taxa de Administração Máxima em % a.a. | I1: {=_xll.ECONOMATICA(_xll.EcoRange(1,-8,26,-8),"Close",,"D-0",,,"ORIGINAL CURRENCY",,"false","true")} -> Fechamento 12Mai26 ajust p/ prov Em moeda orig | J1: {=_xll.ECONOMATICA(_xll.EcoRange(1,-9,26,-9),"Close",,"LATEST",,,"ORIGINAL CURRENCY",,"false","true","Cota em reais",{"tc.pers=3"})} -> Cota em reais | K1: {=_xll.ECONOMATICA(_xll.EcoRange(1,-10,26,-10),"Series Start Date",,,,,,,"false","true")} -> Data do Início da Série | L1: {=_xll.ECONOMATICA(_xll.EcoRange(1,-11,26,-11),"Volatility","FROM START","D-0",,,"ORIGINAL CURRENCY",,"false","true")} -> Volatilidade base anual 12Mai26 desde início Em moeda orig | M1: {=_xll.ECONOMATICA(_xll.EcoRange(1,-12,26,-12),"Net Assets",,"LATEST",,,"ORIGINAL CURRENCY","THOUSANDS","false","true")} -> Patrimônio Mais recente Em moeda orig em milhares
A2: 634468<BraNa> | B2: ARX Denali Advisory Fc FIF RF Créd Priv - Resp Lim | C2: 41888219000156 | D2: 634468 | E2: Renda Fixa Duração Baixa Grau de Investimento | F2: ARX Investimentos Ltda. | G2: BNY Mellon Serviços Financeiros Dtvm S/A | J2: 1.7662261 | K2: 44413 | L2: 0.370749 | M2: 1598464.3
A3: 526886<BraNa> | B3: ARX Everest Advisory Fc FIF RF Cred Priv - Resp Limitada | C3: 35789436000196 | D3: 526886 | E3: Renda Fixa Duração Baixa Grau de Investimento | F3: ARX Investimentos Ltda. | G3: BNY Mellon Serviços Financeiros Dtvm S/A | J3: 1.9418172 | K3: 43866 | L3: 1.0987365 | M3: 424848.58
A4: 601462<BraNa> | B4: ARX Vinson Adv Fc FIF RF Cred Priv - Resp Limitada | C4: 41888492000180 | D4: 601462 | E4: Renda Fixa Duração Baixa Grau de Investimento | F4: ARX Investimentos Ltda. | G4: BNY Mellon Serviços Financeiros Dtvm S/A | J4: 1.7933704 | K4: 44393 | L4: 0.52976793 | M4: 1251713.9
A5: 284491<BraNa> | B5: Capitânia Top Cred Priv Fc FIF RF - Resp Limitada | C5: 13615411000133 | D5: 284491 | E5: Renda Fixa Duração Média Crédito Livre | F5: Capitania Capital | G5: BNY Mellon Serviços Financeiros Dtvm S/A | J5: 5.3371224 | K5: 39589 | L5: 0.88878195 | M5: 203260.47
A6: 677930<BraNa> | B6: Classe Única de Cotas do Absolute Atenas Advisory FI Financeiro em Cota | C6: 48096589000108 | D6: 677930 | E6: Renda Fixa Duração Baixa Grau de Investimento | F6: Absolute Crédito | G6: BTG Pactual Servicos Financeiros S/A Dtv | J6: 1.5686397 | K6: 44862 | L6: 0.26345109 | M6: 734275.08
A7: 678007<BraNa> | B7: Classe Única de Cotas do Absolute Creta Advisory F | C7: 48122126000165 | D7: 678007 | E7: Renda Fixa Duração Baixa Grau de Investimento | F7: Absolute Crédito | G7: BTG Pactual Servicos Financeiros S/A Dtv | J7: 1.5859878 | K7: 44862 | L7: 0.4832305 | M7: 1721026.5
A8: 687138<BraNa> | B8: Classe Única de Cotas do Absolute Olimpia Fundo de | C8: 48986106000132 | D8: 687138 | E8: Multimercados Livre | F8: Absolute Crédito | G8: BTG Pactual Servicos Financeiros S/A Dtv | J8: 1.583209 | K8: 44925 | L8: 0.61119382 | M8: 272263.43
A9: 624977<BraNa> | B9: Classe Unica de Cotas do Af Horizonte Fundo de Inv | C9: 44025131000107 | D9: 624977 | E9: Multimercados Livre | F9: Af Invest Administração de Recursos Ltda | G9: BTG Pactual Servicos Financeiros S/A Dtv | J9: 1.7252344 | K9: 44523 | L9: 0.91291145 | M9: 230557.05
A10: 462276<BraNa> | B10: Classe Única de Cotas do Af Invest Geraes 30 FI Financeiro RF - | C10: 29044189000104 | D10: 462276 | E10: Renda Fixa Duração Livre Grau de Investimento | F10: Af Invest Administração de Recursos Ltda | G10: BTG Pactual Servicos Financeiros S/A Dtv | J10: 2.0633091 | K10: 43187 | L10: 1.101544 | M10: 311423.16
A11: 216658<BraNa> | B11: Classe Única de Cotas do Af Invest Geraes FI Financeiro RF - Cr | C11: 9720734000110 | D11: 216658 | E11: Renda Fixa Duração Livre Grau de Investimento | F11: Af Invest Administração de Recursos Ltda | G11: BTG Pactual Servicos Financeiros S/A Dtv | J11: 5.4968332 | K11: 39702 | L11: 0.63200306 | M11: 539746.11
A12: 531553<BraNa> | B12: Classe Única de Cotas do Riza Lotus Fundo de Inves | C12: 36498670000127 | D12: 531553 | E12: Renda Fixa Duração Livre Grau de Investimento | F12: Riza Líquidos | G12: BTG Pactual Servicos Financeiros S/A Dtv | H12: 0.4 | J12: 1.9132096 | K12: 43907 | L12: 0.33481661 | M12: 3801596.9
A13: 620955<BraNa> | B13: Classe Única de Cotas do Riza Lotus Plus Advisory | C13: 43917493000131 | D13: 620955 | E13: Renda Fixa Duração Livre Grau de Investimento | F13: Riza Líquidos | G13: BTG Pactual Servicos Financeiros S/A Dtv | J13: 1.7399199 | K13: 44498 | L13: 0.89491432 | M13: 498517.97
A14: 489956<BraNa> | B14: Classe Única do Western Asset Total Credit Advisory FIC de Fund | C14: 28320756000137 | D14: 489956 | E14: Renda Fixa Duração Baixa Grau de Investimento | F14: Franklin Templeton Brasil Ltda | G14: Banco BNP Paribas Brasil S/A | J14: 1926.6212 | K14: 43538 | L14: 0.78192199 | M14: 3569168.5
A15: 470473<BraNa> | B15: Daycoval Classic 30 Classe de Investimento RF Cred Priv Resp Limitada | C15: 29250121000173 | D15: 470473 | E15: Renda Fixa Duração Baixa Grau de Investimento | F15: Daycoval Asset Manag | G15: Banco Daycoval S.A. | J15: 2.1051864 | K15: 43283 | L15: 0.60675787 | M15: 865976.73
A16: 259624<BraNa> | B16: Daycoval Classic Classe de Investimento em Cotas de FI RF Cred Priv Resp Limitada Cred Pri | C16: 10783480000168 | D16: 259624 | E16: Renda Fixa Duração Baixa Grau de Investimento | F16: Daycoval Asset Manag | G16: Banco Daycoval S.A. | J16: 5.3789138 | K16: 40389 | L16: 0.38517713 | M16: 2164491.5
A17: 387444<BraNa> | B17: Inter Conservador FI Financeiro RF Cred Priv Responsabili | C17: 20879578000177 | D17: 387444 | E17: Renda Fixa Duração Baixa Grau de Investimento | F17: Inter Asset | G17: Inter Distribuidora de Títulos e Valores | J17: 2.9001288 | K17: 42034 | L17: 0.82942731 | M17: 1344300.3
A18: 456497<BraNa> | B18: Iridium Apollo Fc FIF RF Cred Priv LP - Resp Limitada | C18: 26978438000132 | D18: 456497 | E18: Renda Fixa Duração Livre Grau de Investimento | F18: Iridium Gestão de Recursos Ltda. | G18: BNY Mellon Serviços Financeiros Dtvm S/A | J18: 2.0870277 | K18: 43047 | L18: 0.88568006 | M18: 1387027
A19: 494607<BraNa> | B19: Iridium Titan Advisory Fc FIF RF Cred Priv ? Resp Limitada | C19: 32756812000158 | D19: 494607 | E19: Renda Fixa Duração Livre Crédito Livre | F19: Iridium Gestão de Recursos Ltda. | G19: BNY Mellon Serviços Financeiros Dtvm S/A | J19: 2.0185206 | K19: 43591 | L19: 0.67011672 | M19: 187499.27
A20: 393185<BraNa> | B20: Jgp Select Fc FIF Mult Cred Priv - Resp Limitada | C20: 21946695000179 | D20: 393185 | E20: Multimercados Estratégia Específica | F20: Jgp Gestão de Crédito Ltda. | G20: BNY Mellon Serviços Financeiros Dtvm S/A | J20: 321.29301 | K20: 42118 | L20: 1.5295323 | M20: 347114.09
A21: 635091<BraNa> | B21: Nu Reserva Imediata FIF Cic RF Ref DI Resp Limitad | C21: 42699466000177 | D21: 635091 | E21: Renda Fixa Duração Baixa Grau de Investimento | F21: Nu Asset Management Ltda. | G21: Intrag Dist. de Títu | J21: 1.6933984 | K21: 44574 | L21: 0.44668576 | M21: 2834785.7
A22: 478008<BraNa> | B22: Polo Crédito Corporativo Advisory Fc FIF RF Cred Priv LP - Resp Limitada | C22: 31455879000190 | D22: 478008 | E22: Renda Fixa Duração Livre Crédito Livre | F22: Polo Capital Gestão de Recurso | G22: BNY Mellon Serviços Financeiros Dtvm S/A | J22: 2.1123136 | K22: 43395 | L22: 0.6130043 | M22: 1157810.9
A23: 414972<BraNa> | B23: Polo Total Credit Fc FIF Mult Cred Priv - Resp Limitada | C23: 23601467000192 | D23: 414972 | E23: Multimercados Livre | F23: Polo Capital Gestão de Recurso | G23: BNY Mellon Serviços Financeiros Dtvm S/A | J23: 3.2810512 | K23: 42432 | L23: 3.2466781 | M23: 73457.618
A24: 361445<BraNa> | B24: Porto Seguro FIF RF Ref DI Créd Priv Resp Limitada | C24: 18719154000101 | D24: 361445 | E24: Renda Fixa Duração Baixa Grau de Investimento | F24: Porto Seguro Investimentos Ltda. | G24: Intrag Dist. de Títu | J24: 3.3245078 | K24: 41698 | L24: 0.54447902 | M24: 6892815.2
... A27: 494089<BraNa> | B27: Sparta Top Adv Fc FI RF Cred Priv LP - Resp Limitada | C27: 32846811000102 | D27: 494089 | E27: Renda Fixa Duração Média Grau de Investimento | F27: Sparta Administradora de Recursos Ltda | G27: BNY Mellon Serviços Financeiros Dtvm S/A | J27: 1.9438378 | K27: 43579 | L27: 0.83844845 | M27: 574548.93

Sheet Correlação
